Workbook

Sheet Inst_tentativas
B2: BD GISTM — Modelo por Principios (prototipo)
B4: Este archivo reestructura la base BD_GISTM.xlsx en un modelo relacional de 3 tablas para que el avance se calcule por Principio, permitiendo que un mismo documento aporte a varios Principios sin duplicar su información.
B9: Hoja | C9: Qué contiene / cómo se usa
B10: 1. Documentos | C10: Un documento = una sola fila. Aquí editas estado, % avance, fechas, consultor, URL, etc. Nunca se repite.
B12: 2. Criterios GISTM | C12: Catálogo fijo del estándar: Tema > Principio > Requisito > Criterio, con su ponderación. No cambia por proyecto.
B14: 3. Documento_x_Criterio | C14: Tabla puente: una fila por cada vínculo Documento-Criterio. Aquí es donde un documento puede aparecer varias veces si aporta a varios Principios. Incluye "% Contribución" para casos donde el documento cubre solo parcialmente un criterio.
B16: 4. Avance por Principio | C16: Calculado automáticamente con fórmulas (SUMIFS/SUMPRODUCT) a partir de la tabla puente. No se edita a mano.
B18: 5. Avance por Tema | C18: Mismo cálculo agregado a nivel de Tema.
B21: Cómo agregar un documento nuevo que cubre 2 Principios
B22: 1) Agrega UNA fila en "Documentos" con sus datos (estado, % avance, etc.) y un ID_Documento nuevo.
B23: 2) En "Documento_x_Criterio" agrega las filas (una por cada criterio al que aporta), usando el mismo ID_Documento y el ID_Criterio correspondiente.
B24: 3) "Avance por Principio" se actualiza solo, sin tocar fórmulas.

Sheet Documentos
A1: ID_Documento | B1: Documento | C1: Tipo Documento | D1: Código | E1: Estado | F1: % Avance Individual | G1: Consultor | H1: Área Responsable | I1: Fecha Iniciado | J1: Fecha RevA | K1: Fecha RevB | L1: Fecha Rev0 | M1: Frecuencia (meses) | N1: Caducidad | O1: URL | P1: Compañía | Q1: Depósito | R1: Capacidad | S1: Vida Útil
A2: D001 | B2: Compromiso de DDHH | C2: Política | D2: GA-DOC-01-2024 | E2: =IF(AND(L2>0,L2<>"-"),"Rev0",IF(AND(K2>0,K2<>"-"),"RevB",IF(AND(J2>0,J2<>"-"),"RevA",IF(AND(I2>0,I2<>"-"),"Iniciado","No Asignado")))) -> Rev0 | F2: {=_xlfn.IFS(E2="No Asignado",0,E2="Iniciado",0.2,E2="RevA",0.4,E2="RevB",0.7,E2="Rev0",1)} -> 1 | G2: Consultor 1 | H2: Sustentabilidad | I2: 45292 | J2: 45312 | K2: 45337 | L2: 45717 | M2: 36 | N2: 46797 | O2: https://drive.google.com/drive/folders/1IaEo6qPMz_Vb8OOQY3e1RIre4Fj4qXZL?usp=drive_link | P2: Mining Company | Q2: Embalse N°1 | R2: 2000 M Ton | S2: 20 años
A3: D002 | B3: Informe de Proceso de Debida Diligencia | C3: Informe | D3: GA-DOC-01-2024 | E3: =IF(AND(L3>0,L3<>"-"),"Rev0",IF(AND(K3>0,K3<>"-"),"RevB",IF(AND(J3>0,J3<>"-"),"RevA",IF(AND(I3>0,I3<>"-"),"Iniciado","No Asignado")))) -> RevB | F3: {=_xlfn.IFS(E3="No Asignado",0,E3="Iniciado",0.2,E3="RevA",0.4,E3="RevB",0.7,E3="Rev0",1)} -> 0.7 | G3: Consultor 1 | H3: Sustentabilidad | I3: 45292 | J3: 45312 | K3: 45337 | L3: - | M3: 12 | N3: - | O3: https://drive.google.com/drive/folders/1IaEo6qPMz_Vb8OOQY3e1RIre4Fj4qXZL?usp=drive_link | P3: Mining Company | Q3: Embalse N°1 | R3: 2000 M Ton | S3: 20 años
A4: D003 | B4: Nota Técnica No Afectación Pueblos Indígenas | C4: Nota Técnica | D4: GA-DOC-01-2024 | E4: =IF(AND(L4>0,L4<>"-"),"Rev0",IF(AND(K4>0,K4<>"-"),"RevB",IF(AND(J4>0,J4<>"-"),"RevA",IF(AND(I4>0,I4<>"-"),"Iniciado","No Asignado")))) -> Iniciado | F4: {=_xlfn.IFS(E4="No Asignado",0,E4="Iniciado",0.2,E4="RevA",0.4,E4="RevB",0.7,E4="Rev0",1)} -> 0.2 | G4: Consultor 1 | H4: Sustentabilidad | I4: 45292 | J4: - | K4: - | L4: - | M4: 6 | N4: - | O4: https://drive.google.com/drive/folders/1IaEo6qPMz_Vb8OOQY3e1RIre4Fj4qXZL?usp=drive_link | P4: Mining Company | Q4: Embalse N°1 | R4: 2000 M Ton | S4: 20 años
A5: D004 | B5: Informe de Identificación de Grupos Potenciales Afectados | C5: Informe | D5: GA-DOC-01-2024 | E5: =IF(AND(L5>0,L5<>"-"),"Rev0",IF(AND(K5>0,K5<>"-"),"RevB",IF(AND(J5>0,J5<>"-"),"RevA",IF(AND(I5>0,I5<>"-"),"Iniciado","No Asignado")))) -> Iniciado | F5: {=_xlfn.IFS(E5="No Asignado",0,E5="Iniciado",0.2,E5="RevA",0.4,E5="RevB",0.7,E5="Rev0",1)} -> 0.2 | G5: Consultor 3 | H5: Sustentabilidad | I5: 45292 | J5: - | K5: - | L5: - | M5: 12 | N5: - | O5: https://drive.google.com/drive/folders/1IaEo6qPMz_Vb8OOQY3e1RIre4Fj4qXZL?usp=drive_link | P5: Mining Company | Q5: Embalse N°1 | R5: 2000 M Ton | S5: 20 años
A6: D005 | B6: Procedimiento de Comunicación | C6: Procedimiento | D6: GA-DOC-01-2024 | E6: =IF(AND(L6>0,L6<>"-"),"Rev0",IF(AND(K6>0,K6<>"-"),"RevB",IF(AND(J6>0,J6<>"-"),"RevA",IF(AND(I6>0,I6<>"-"),"Iniciado","No Asignado")))) -> Iniciado | F6: {=_xlfn.IFS(E6="No Asignado",0,E6="Iniciado",0.2,E6="RevA",0.4,E6="RevB",0.7,E6="Rev0",1)} -> 0.2 | G6: Consultor 3 | H6: Sustentabilidad | I6: 45292 | J6: - | K6: - | L6: - | M6: 6 | N6: - | O6: https://drive.google.com/drive/folders/1IaEo6qPMz_Vb8OOQY3e1RIre4Fj4qXZL?usp=drive_link | P6: Mining Company | Q6: Embalse N°1 | R6: 2000 M Ton | S6: 20 años
A7: D006 | B7: Informe de Contexto Social, Económico y Ambiental | C7: Informe | D7: GA-DOC-01-2024 | E7: =IF(AND(L7>0,L7<>"-"),"Rev0",IF(AND(K7>0,K7<>"-"),"RevB",IF(AND(J7>0,J7<>"-"),"RevA",IF(AND(I7>0,I7<>"-"),"Iniciado","No Asignado")))) -> Iniciado | F7: {=_xlfn.IFS(E7="No Asignado",0,E7="Iniciado",0.2,E7="RevA",0.4,E7="RevB",0.7,E7="Rev0",1)} -> 0.2 | G7: Consultor 3 | H7: Medio Ambiente | I7: 45292 | J7: - | K7: - | L7: - | M7: 12 | N7: - | O7: https://drive.google.com/drive/folders/1IaEo6qPMz_Vb8OOQY3e1RIre4Fj4qXZL?usp=drive_link | P7: Mining Company | Q7: Embalse N°1 | R7: 2000 M Ton | S7: 20 años
A8: D007 | B8: Informe de Caracterización del Sitio | C8: Informe | D8: GA-DOC-01-2024 | E8: =IF(AND(L8>0,L8<>"-"),"Rev0",IF(AND(K8>0,K8<>"-"),"RevB",IF(AND(J8>0,J8<>"-"),"RevA",IF(AND(I8>0,I8<>"-"),"Iniciado","No Asignado")))) -> Rev0 | F8: {=_xlfn.IFS(E8="No Asignado",0,E8="Iniciado",0.2,E8="RevA",0.4,E8="RevB",0.7,E8="Rev0",1)} -> 1 | G8: Consultor 3 | H8: Medio Ambiente | I8: 45332 | J8: 45347 | K8: 45356 | L8: 45731 | M8: 12 | N8: 46091 | O8: https://drive.google.com/drive/folders/1IaEo6qPMz_Vb8OOQY3e1RIre4Fj4qXZL?usp=drive_link | P8: Mining Company | Q8: Embalse N°1 | R8: 2000 M Ton | S8: 20 años
A9: D008 | B9: Informe Análisis de Rotura de Presa (DBA) | C9: Informe | D9: GA-DOC-01-2024 | E9: =IF(AND(L9>0,L9<>"-"),"Rev0",IF(AND(K9>0,K9<>"-"),"RevB",IF(AND(J9>0,J9<>"-"),"RevA",IF(AND(I9>0,I9<>"-"),"Iniciado","No Asignado")))) -> Rev0 | F9: {=_xlfn.IFS(E9="No Asignado",0,E9="Iniciado",0.2,E9="RevA",0.4,E9="RevB",0.7,E9="Rev0",1)} -> 1 | G9: Consultor 1 | H9: Medio Ambiente | I9: 45332 | J9: 45347 | K9: 45356 | L9: 45731 | M9: 12 | N9: 46091 | O9: https://drive.google.com/drive/folders/1IaEo6qPMz_Vb8OOQY3e1RIre4Fj4qXZL?usp=drive_link | P9: Mining Company | Q9: Embalse N°1 | R9: 2000 M Ton | S9: 20 años
A10: D009 | B10: Informe Exposición y Vulnerabilidad | C10: Informe | D10: GA-DOC-01-2024 | E10: =IF(AND(L10>0,L10<>"-"),"Rev0",IF(AND(K10>0,K10<>"-"),"RevB",IF(AND(J10>0,J10<>"-"),"RevA",IF(AND(I10>0,I10<>"-"),"Iniciado","No Asignado")))) -> Rev0 | F10: {=_xlfn.IFS(E10="No Asignado",0,E10="Iniciado",0.2,E10="RevA",0.4,E10="RevB",0.7,E10="Rev0",1)} -> 1 | G10: Consultor 1 | H10: Medio Ambiente | I10: 45332 | J10: 45347 | K10: 45356 | L10: 45731 | M10: 12 | N10: 46091 | O10: https://drive.google.com/drive/folders/1IaEo6qPMz_Vb8OOQY3e1RIre4Fj4qXZL?usp=drive_link | P10: Mining Company | Q10: Embalse N°1 | R10: 2000 M Ton | S10: 20 años
A11: D010 | B11: Informe de Hidrología y Evaporación con Cambio Climático | C11: Informe | D11: GA-DOC-01-2024 | E11: =IF(AND(L11>0,L11<>"-"),"Rev0",IF(AND(K11>0,K11<>"-"),"RevB",IF(AND(J11>0,J11<>"-"),"RevA",IF(AND(I11>0,I11<>"-"),"Iniciado","No Asignado")))) -> RevA | F11: {=_xlfn.IFS(E11="No Asignado",0,E11="Iniciado",0.2,E11="RevA",0.4,E11="RevB",0.7,E11="Rev0",1)} -> 0.4 | G11: Consultor 1 | H11: Medio Ambiente | I11: 45332 | J11: 45347 | K11: - | L11: - | M11: 12 | N11: - | O11: https://drive.google.com/drive/folders/1IaEo6qPMz_Vb8OOQY3e1RIre4Fj4qXZL?usp=drive_link | P11: Mining Company | Q11: Embalse N°1 | R11: 2000 M Ton | S11: 20 años
A12: D011 | B12: Informe de Análisis de Alternativas | C12: Informe | D12: GA-DOC-01-2024 | E12: =IF(AND(L12>0,L12<>"-"),"Rev0",IF(AND(K12>0,K12<>"-"),"RevB",IF(AND(J12>0,J12<>"-"),"RevA",IF(AND(I12>0,I12<>"-"),"Iniciado","No Asignado")))) -> Iniciado | F12: {=_xlfn.IFS(E12="No Asignado",0,E12="Iniciado",0.2,E12="RevA",0.4,E12="RevB",0.7,E12="Rev0",1)} -> 0.2 | G12: Consultor 1 | H12: Medio Ambiente | I12: 45332 | J12: - | K12: - | L12: - | M12: 12 | N12: - | O12: https://drive.google.com/drive/folders/1IaEo6qPMz_Vb8OOQY3e1RIre4Fj4qXZL?usp=drive_link | P12: Mining Company | Q12: Embalse N°1 | R12: 2000 M Ton | S12: 20 años
A13: D012 | B13: Procedimiento de Mejora continua | C13: Procedimiento | D13: GA-DOC-01-2024 | E13: =IF(AND(L13>0,L13<>"-"),"Rev0",IF(AND(K13>0,K13<>"-"),"RevB",IF(AND(J13>0,J13<>"-"),"RevA",IF(AND(I13>0,I13<>"-"),"Iniciado","No Asignado")))) -> Iniciado | F13: {=_xlfn.IFS(E13="No Asignado",0,E13="Iniciado",0.2,E13="RevA",0.4,E13="RevB",0.7,E13="Rev0",1)} -> 0.2 | G13: Consultor 1 | H13: Medio Ambiente | I13: 45332 | J13: - | K13: - | L13: - | M13: 6 | N13: - | O13: https://drive.google.com/drive/folders/1IaEo6qPMz_Vb8OOQY3e1RIre4Fj4qXZL?usp=drive_link | P13: Mining Company | Q13: Embalse N°1 | R13: 2000 M Ton | S13: 20 años
A14: D013 | B14: Informe de impactos sociales, medioambientales y económicos | C14: Informe | D14: GA-DOC-01-2024 | E14: =IF(AND(L14>0,L14<>"-"),"Rev0",IF(AND(K14>0,K14<>"-"),"RevB",IF(AND(J14>0,J14<>"-"),"RevA",IF(AND(I14>0,I14<>"-"),"Iniciado","No Asignado")))) -> Iniciado | F14: {=_xlfn.IFS(E14="No Asignado",0,E14="Iniciado",0.2,E14="RevA",0.4,E14="RevB",0.7,E14="Rev0",1)} -> 0.2 | G14: Consultor 1 | H14: Medio Ambiente | I14: 45332 | J14: - | K14: - | L14: - | M14: 12 | N14: - | O14: https://drive.google.com/drive/folders/1IaEo6qPMz_Vb8OOQY3e1RIre4Fj4qXZL?usp=drive_link | P14: Mining Company | Q14: Embalse N°1 | R14: 2000 M Ton | S14: 20 años
A15: D014 | B15: Procedimiento de Gestión del Cambio | C15: Procedimiento | D15: GA-DOC-01-2024 | E15: =IF(AND(L15>0,L15<>"-"),"Rev0",IF(AND(K15>0,K15<>"-"),"RevB",IF(AND(J15>0,J15<>"-"),"RevA",IF(AND(I15>0,I15<>"-"),"Iniciado","No Asignado")))) -> Iniciado | F15: {=_xlfn.IFS(E15="No Asignado",0,E15="Iniciado",0.2,E15="RevA",0.4,E15="RevB",0.7,E15="Rev0",1)} -> 0.2 | G15: Consultor 1 | H15: Medio Ambiente | I15: 45332 | J15: - | K15: - | L15: - | M15: 6 | N15: - | O15: https://drive.google.com/drive/folders/1IaEo6qPMz_Vb8OOQY3e1RIre4Fj4qXZL?usp=drive_link | P15: Mining Company | Q15: Embalse N°1 | R15: 2000 M Ton | S15: 20 años
A16: D015 | B16: Informe Clasificación por Consecuencia | C16: Informe | D16: GA-DOC-01-2024 | E16: =IF(AND(L16>0,L16<>"-"),"Rev0",IF(AND(K16>0,K16<>"-"),"RevB",IF(AND(J16>0,J16<>"-"),"RevA",IF(AND(I16>0,I16<>"-"),"Iniciado","No Asignado")))) -> Iniciado | F16: {=_xlfn.IFS(E16="No Asignado",0,E16="Iniciado",0.2,E16="RevA",0.4,E16="RevB",0.7,E16="Rev0",1)} -> 0.2 | G16: Consultor 2 | H16: Operaciones | I16: 45332 | J16: - | K16: - | L16: - | M16: 12 | N16: - | O16: https://drive.google.com/drive/folders/1IaEo6qPMz_Vb8OOQY3e1RIre4Fj4qXZL?usp=drive_link | P16: Mining Company | Q16: Embalse N°1 | R16: 2000 M Ton | S16: 20 años
A17: D016 | B17: Informe de Bases de Diseño | C17: Informe | D17: GA-DOC-01-2024 | E17: =IF(AND(L17>0,L17<>"-"),"Rev0",IF(AND(K17>0,K17<>"-"),"RevB",IF(AND(J17>0,J17<>"-"),"RevA",IF(AND(I17>0,I17<>"-"),"Iniciado","No Asignado")))) -> Iniciado | F17: {=_xlfn.IFS(E17="No Asignado",0,E17="Iniciado",0.2,E17="RevA",0.4,E17="RevB",0.7,E17="Rev0",1)} -> 0.2 | G17: Consultor 2 | H17: Operaciones | I17: 45337 | J17: - | K17: - | L17: - | M17: 12 | N17: - | O17: https://drive.google.com/drive/folders/1IaEo6qPMz_Vb8OOQY3e1RIre4Fj4qXZL?usp=drive_link | P17: Mining Company | Q17: Embalse N°1 | R17: 2000 M Ton | S17: 20 años
A18: D017 | B18: Nota Técnica Pérdida Incremental | C18: Nota Técnica | D18: GA-DOC-01-2024 | E18: =IF(AND(L18>0,L18<>"-"),"Rev0",IF(AND(K18>0,K18<>"-"),"RevB",IF(AND(J18>0,J18<>"-"),"RevA",IF(AND(I18>0,I18<>"-"),"Iniciado","No Asignado")))) -> RevA | F18: {=_xlfn.IFS(E18="No Asignado",0,E18="Iniciado",0.2,E18="RevA",0.4,E18="RevB",0.7,E18="Rev0",1)} -> 0.4 | G18: Consultor 2 | H18: Operaciones | I18: 45337 | J18: 45347 | K18: - | L18: - | M18: 6 | N18: - | O18: https://drive.google.com/drive/folders/1IaEo6qPMz_Vb8OOQY3e1RIre4Fj4qXZL?usp=drive_link | P18: Mining Company | Q18: Embalse N°1 | R18: 2000 M Ton | S18: 20 años
A19: D018 | B19: Nota Técnica Análisis Multicriterio en TMS | C19: Nota Técnica | D19: GA-DOC-01-2024 | E19: =IF(AND(L19>0,L19<>"-"),"Rev0",IF(AND(K19>0,K19<>"-"),"RevB",IF(AND(J19>0,J19<>"-"),"RevA",IF(AND(I19>0,I19<>"-"),"Iniciado","No Asignado")))) -> RevA | F19: {=_xlfn.IFS(E19="No Asignado",0,E19="Iniciado",0.2,E19="RevA",0.4,E19="RevB",0.7,E19="Rev0",1)} -> 0.4 | G19: Consultor 2 | H19: Operaciones | I19: 45337 | J19: 45347 | K19: - | L19: - | M19: 6 | N19: - | O19: https://drive.google.com/drive/folders/1IaEo6qPMz_Vb8OOQY3e1RIre4Fj4qXZL?usp=drive_link | P19: Mining Company | Q19: Embalse N°1 | R19: 2000 M Ton | S19: 20 años
A20: D019 | B20: Informe Anual de Desempeño del Depósito | C20: Informe | D20: GA-DOC-01-2024 | E20: =IF(AND(L20>0,L20<>"-"),"Rev0",IF(AND(K20>0,K20<>"-"),"RevB",IF(AND(J20>0,J20<>"-"),"RevA",IF(AND(I20>0,I20<>"-"),"Iniciado","No Asignado")))) -> RevB | F20: {=_xlfn.IFS(E20="No Asignado",0,E20="Iniciado",0.2,E20="RevA",0.4,E20="RevB",0.7,E20="Rev0",1)} -> 0.7 | G20: Consultor 2 | H20: Operaciones | I20: 45337 | J20: 45347 | K20: 45354 | L20: - | M20: 12 | N20: - | O20: https://drive.google.com/drive/folders/1IaEo6qPMz_Vb8OOQY3e1RIre4Fj4qXZL?usp=drive_link | P20: Mining Company | Q20: Embalse N°1 | R20: 2000 M Ton | S20: 20 años
A21: D020 | B21: Balance Hídrico | C21: Informe | D21: GA-DOC-01-2024 | E21: =IF(AND(L21>0,L21<>"-"),"Rev0",IF(AND(K21>0,K21<>"-"),"RevB",IF(AND(J21>0,J21<>"-"),"RevA",IF(AND(I21>0,I21<>"-"),"Iniciado","No Asignado")))) -> Rev0 | F21: {=_xlfn.IFS(E21="No Asignado",0,E21="Iniciado",0.2,E21="RevA",0.4,E21="RevB",0.7,E21="Rev0",1)} -> 1 | G21: Consultor 2 | H21: Operaciones | I21: 45337 | J21: 45347 | K21: 45354 | L21: 45740 | M21: 12 | N21: 46100 | O21: https://drive.google.com/drive/folders/1IaEo6qPMz_Vb8OOQY3e1RIre4Fj4qXZL?usp=drive_link | P21: Mining Company | Q21: Embalse N°1 | R21: 2000 M Ton | S21: 20 años
A22: D021 | B22: Análisis FMEA | C22: Informe | D22: GA-DOC-01-2024 | E22: =IF(AND(L22>0,L22<>"-"),"Rev0",IF(AND(K22>0,K22<>"-"),"RevB",IF(AND(J22>0,J22<>"-"),"RevA",IF(AND(I22>0,I22<>"-"),"Iniciado","No Asignado")))) -> Rev0 | F22: {=_xlfn.IFS(E22="No Asignado",0,E22="Iniciado",0.2,E22="RevA",0.4,E22="RevB",0.7,E22="Rev0",1)} -> 1 | G22: Consultor 1 | H22: Operaciones | I22: 45337 | J22: 45347 | K22: 45354 | L22: 45740 | M22: 12 | N22: 46100 | O22: https://drive.google.com/drive/folders/1IaEo6qPMz_Vb8OOQY3e1RIre4Fj4qXZL?usp=drive_link | P22: Mining Company | Q22: Embalse N°1 | R22: 2000 M Ton | S22: 20 años
A23: D022 | B23: Plan de cierre | C23: Informe | D23: GA-DOC-01-2024 | E23: =IF(AND(L23>0,L23<>"-"),"Rev0",IF(AND(K23>0,K23<>"-"),"RevB",IF(AND(J23>0,J23<>"-"),"RevA",IF(AND(I23>0,I23<>"-"),"Iniciado","No Asignado")))) -> Rev0 | F23: {=_xlfn.IFS(E23="No Asignado",0,E23="Iniciado",0.2,E23="RevA",0.4,E23="RevB",0.7,E23="Rev0",1)} -> 1 | G23: Consultor 1 | H23: Operaciones | I23: 45340 | J23: 45347 | K23: 45354 | L23: 45741 | M23: 12 | N23: 46101 | O23: https://drive.google.com/drive/folders/1IaEo6qPMz_Vb8OOQY3e1RIre4Fj4qXZL?usp=drive_link | P23: Mining Company | Q23: Embalse N°1 | R23: 2000 M Ton | S23: 20 años
A24: D023 | B24: Reporte ALARP | C24: Informe | D24: GA-DOC-01-2024 | E24: =IF(AND(L24>0,L24<>"-"),"Rev0",IF(AND(K24>0,K24<>"-"),"RevB",IF(AND(J24>0,J24<>"-"),"RevA",IF(AND(I24>0,I24<>"-"),"Iniciado","No Asignado")))) -> RevA | F24: {=_xlfn.IFS(E24="No Asignado",0,E24="Iniciado",0.2,E24="RevA",0.4,E24="RevB",0.7,E24="Rev0",1)} -> 0.4 | G24: Consultor 1 | H24: Operaciones | I24: 45340 | J24: 45347 | K24: - | L24: - | M24: 12 | N24: - | O24: https://drive.google.com/drive/folders/1IaEo6qPMz_Vb8OOQY3e1RIre4Fj4qXZL?usp=drive_link | P24: Mining Company | Q24: Embalse N°1 | R24: 2000 M Ton | S24: 20 años
A25: D024 | B25: Nota Técnica Comunidades Aledañas | C25: Nota Técnica | D25: GA-DOC-01-2024 | E25: =IF(AND(L25>0,L25<>"-"),"Rev0",IF(AND(K25>0,K25<>"-"),"RevB",IF(AND(J25>0,J25<>"-"),"RevA",IF(AND(I25>0,I25<>"-"),"Iniciado","No Asignado")))) -> Iniciado | F25: {=_xlfn.IFS(E25="No Asignado",0,E25="Iniciado",0.2,E25="RevA",0.4,E25="RevB",0.7,E25="Rev0",1)} -> 0.2 | G25: Consultor 1 | H25: Operaciones | I25: 45340 | J25: - | K25: - | L25: - | M25: 6 | N25: - | O25: https://drive.google.com/drive/folders/1IaEo6qPMz_Vb8OOQY3e1RIre4Fj4qXZL?usp=drive_link | P25: Mining Company | Q25: Embalse N°1 | R25: 2000 M Ton | S25: 20 años
A26: D025 | B26: Reporte de Registro de Construcción (CRR) | C26: Informe | D26: GA-DOC-01-2024 | E26: =IF(AND(L26>0,L26<>"-"),"Rev0",IF(AND(K26>0,K26<>"-"),"RevB",IF(AND(J26>0,J26<>"-"),"RevA",IF(AND(I26>0,I26<>"-"),"Iniciado","No Asignado")))) -> Iniciado | F26: {=_xlfn.IFS(E26="No Asignado",0,E26="Iniciado",0.2,E26="RevA",0.4,E26="RevB",0.7,E26="Rev0",1)} -> 0.2 | G26: Consultor 3 | H26: Operaciones | I26: 45340 | J26: - | K26: - | L26: - | M26: 12 | N26: - | O26: https://drive.google.com/drive/folders/1IaEo6qPMz_Vb8OOQY3e1RIre4Fj4qXZL?usp=drive_link | P26: Mining Company | Q26: Embalse N°1 | R26: 2000 M Ton | S26: 20 años
A27: D026 | B27: Informe Verificación construcción contra intención de diseño (CDIV) | C27: Informe | D27: GA-DOC-01-2024 | E27: =IF(AND(L27>0,L27<>"-"),"Rev0",IF(AND(K27>0,K27<>"-"),"RevB",IF(AND(J27>0,J27<>"-"),"RevA",IF(AND(I27>0,I27<>"-"),"Iniciado","No Asignado")))) -> Iniciado | F27: {=_xlfn.IFS(E27="No Asignado",0,E27="Iniciado",0.2,E27="RevA",0.4,E27="RevB",0.7,E27="Rev0",1)} -> 0.2 | G27: Consultor 3 | H27: Operaciones | I27: 45340 | J27: - | K27: - | L27: - | M27: 12 | N27: - | O27: https://drive.google.com/drive/folders/1IaEo6qPMz_Vb8OOQY3e1RIre4Fj4qXZL?usp=drive_link | P27: Mining Company | Q27: Embalse N°1 | R27: 2000 M Ton | S27: 20 años
A28: D027 | B28: Manual Articulador TMS | C28: Manual | D28: GA-DOC-01-2024 | E28: =IF(AND(L28>0,L28<>"-"),"Rev0",IF(AND(K28>0,K28<>"-"),"RevB",IF(AND(J28>0,J28<>"-"),"RevA",IF(AND(I28>0,I28<>"-"),"Iniciado","No Asignado")))) -> Iniciado | F28: {=_xlfn.IFS(E28="No Asignado",0,E28="Iniciado",0.2,E28="RevA",0.4,E28="RevB",0.7,E28="Rev0",1)} -> 0.2 | G28: Consultor 3 | H28: Operaciones | I28: 45340 | J28: - | K28: - | L28: - | M28: 12 | N28: - | O28: https://drive.google.com/drive/folders/1IaEo6qPMz_Vb8OOQY3e1RIre4Fj4qXZL?usp=drive_link | P28: Mining Company | Q28: Embalse N°1 | R28: 2000 M Ton | S28: 20 años
A29: D028 | B29: Manual Operación, Mantención y Vigilancia (OMS) | C29: Manual | D29: GA-DOC-01-2024 | E29: =IF(AND(L29>0,L29<>"-"),"Rev0",IF(AND(K29>0,K29<>"-"),"RevB",IF(AND(J29>0,J29<>"-"),"RevA",IF(AND(I29>0,I29<>"-"),"Iniciado","No Asignado")))) -> Iniciado | F29: {=_xlfn.IFS(E29="No Asignado",0,E29="Iniciado",0.2,E29="RevA",0.4,E29="RevB",0.7,E29="Rev0",1)} -> 0.2 | G29: Consultor 3 | H29: Operaciones | I29: 45340 | J29: - | K29: - | L29: - | M29: 12 | N29: - | O29: https://drive.google.com/drive/folders/1IaEo6qPMz_Vb8OOQY3e1RIre4Fj4qXZL?usp=drive_link | P29: Mining Company | Q29: Embalse N°1 | R29: 2000 M Ton | S29: 20 años
A30: D029 | B30: Manual Sistema Gestión Medioambiental y Social | C30: Manual | D30: GA-DOC-01-2024 | E30: =IF(AND(L30>0,L30<>"-"),"Rev0",IF(AND(K30>0,K30<>"-"),"RevB",IF(AND(J30>0,J30<>"-"),"RevA",IF(AND(I30>0,I30<>"-"),"Iniciado","No Asignado")))) -> Iniciado | F30: {=_xlfn.IFS(E30="No Asignado",0,E30="Iniciado",0.2,E30="RevA",0.4,E30="RevB",0.7,E30="Rev0",1)} -> 0.2 | G30: Consultor 3 | H30: Operaciones | I30: 45340 | J30: - | K30: - | L30: - | M30: 12 | N30: - | O30: https://drive.google.com/drive/folders/1IaEo6qPMz_Vb8OOQY3e1RIre4Fj4qXZL?usp=drive_link | P30: Mining Company | Q30: Embalse N°1 | R30: 2000 M Ton | S30: 20 años
A31: D030 | B31: Programa QA/QC | C31: Informe | D31: GA-DOC-01-2024 | E31: =IF(AND(L31>0,L31<>"-"),"Rev0",IF(AND(K31>0,K31<>"-"),"RevB",IF(AND(J31>0,J31<>"-"),"RevA",IF(AND(I31>0,I31<>"-"),"Iniciado","No Asignado")))) -> Iniciado | F31: {=_xlfn.IFS(E31="No Asignado",0,E31="Iniciado",0.2,E31="RevA",0.4,E31="RevB",0.7,E31="Rev0",1)} -> 0.2 | G31: Consultor 3 | H31: Operaciones | I31: 45342 | J31: - | K31: - | L31: - | M31: 12 | N31: - | O31: https://drive.google.com/drive/folders/1IaEo6qPMz_Vb8OOQY3e1RIre4Fj4qXZL?usp=drive_link | P31: Mining Company | Q31: Embalse N°1 | R31: 2000 M Ton | S31: 20 años
A32: D031 | B32: Plan de Capacitaciones | C32: Informe | D32: GA-DOC-01-2024 | E32: =IF(AND(L32>0,L32<>"-"),"Rev0",IF(AND(K32>0,K32<>"-"),"RevB",IF(AND(J32>0,J32<>"-"),"RevA",IF(AND(I32>0,I32<>"-"),"Iniciado","No Asignado")))) -> Rev0 | F32: {=_xlfn.IFS(E32="No Asignado",0,E32="Iniciado",0.2,E32="RevA",0.4,E32="RevB",0.7,E32="Rev0",1)} -> 1 | G32: Consultor 3 | H32: Operaciones | I32: 45342 | J32: 45352 | K32: 45366 | L32: 45751 | M32: 12 | N32: 46111 | O32: https://drive.google.com/drive/folders/1IaEo6qPMz_Vb8OOQY3e1RIre4Fj4qXZL?usp=drive_link | P32: Mining Company | Q32: Embalse N°1 | R32: 2000 M Ton | S32: 20 años
A33: D032 | B33: Informe de responsabilidad ante desviaciones (DAR) | C33: Informe | D33: GA-DOC-01-2024 | E33: =IF(AND(L33>0,L33<>"-"),"Rev0",IF(AND(K33>0,K33<>"-"),"RevB",IF(AND(J33>0,J33<>"-"),"RevA",IF(AND(I33>0,I33<>"-"),"Iniciado","No Asignado")))) -> Rev0 | F33: {=_xlfn.IFS(E33="No Asignado",0,E33="Iniciado",0.2,E33="RevA",0.4,E33="RevB",0.7,E33="Rev0",1)} -> 1 | G33: Consultor 3 | H33: Operaciones | I33: 45342 | J33: 45352 | K33: 45366 | L33: 45751 | M33: 12 | N33: 46111 | O33: https://drive.google.com/drive/folders/1IaEo6qPMz_Vb8OOQY3e1RIre4Fj4qXZL?usp=drive_link | P33: Mining Company | Q33: Embalse N°1 | R33: 2000 M Ton | S33: 20 años
A34: D033 | B34: Programa de Monitoreo Integrado | C34: Informe | D34: GA-DOC-01-2024 | E34: =IF(AND(L34>0,L34<>"-"),"Rev0",IF(AND(K34>0,K34<>"-"),"RevB",IF(AND(J34>0,J34<>"-"),"RevA",IF(AND(I34>0,I34<>"-"),"Iniciado","No Asignado")))) -> RevB | F34: {=_xlfn.IFS(E34="No Asignado",0,E34="Iniciado",0.2,E34="RevA",0.4,E34="RevB",0.7,E34="Rev0",1)} -> 0.7 | G34: Consultor 3 | H34: Operaciones | I34: 45342 | J34: 45352 | K34: 45366 | L34: - | M34: 12 | N34: - | O34: https://drive.google.com/drive/folders/1IaEo6qPMz_Vb8OOQY3e1RIre4Fj4qXZL?usp=drive_link | P34: Mining Company | Q34: Embalse N°1 | R34: 2000 M Ton | S34: 20 años
A35: D034 | B35: Informes periódicos del EoR | C35: Informe | D35: GA-DOC-01-2024 | E35: =IF(AND(L35>0,L35<>"-"),"Rev0",IF(AND(K35>0,K35<>"-"),"RevB",IF(AND(J35>0,J35<>"-"),"RevA",IF(AND(I35>0,I35<>"-"),"Iniciado","No Asignado")))) -> RevA | F35: {=_xlfn.IFS(E35="No Asignado",0,E35="Iniciado",0.2,E35="RevA",0.4,E35="RevB",0.7,E35="Rev0",1)} -> 0.4 | G35: Consultor 1 | H35: Operaciones | I35: 45342 | J35: 45352 | K35: - | L35: - | M35: 12 | N35: - | O35: https://drive.google.com/drive/folders/1IaEo6qPMz_Vb8OOQY3e1RIre4Fj4qXZL?usp=drive_link | P35: Mining Company | Q35: Embalse N°1 | R35: 2000 M Ton | S35: 20 años
A36: D035 | B36: Plan de Respuesta de Acción Desencadenante (TARPS) | C36: Informe | D36: GA-DOC-01-2024 | E36: =IF(AND(L36>0,L36<>"-"),"Rev0",IF(AND(K36>0,K36<>"-"),"RevB",IF(AND(J36>0,J36<>"-"),"RevA",IF(AND(I36>0,I36<>"-"),"Iniciado","No Asignado")))) -> No Asignado | F36: {=_xlfn.IFS(E36="No Asignado",0,E36="Iniciado",0.2,E36="RevA",0.4,E36="RevB",0.7,E36="Rev0",1)} -> 0 | G36: Consultor 1 | H36: Operaciones | I36: 0 | J36: - | K36: - | L36: - | M36: 12 | N36: - | O36: https://drive.google.com/drive/folders/1IaEo6qPMz_Vb8OOQY3e1RIre4Fj4qXZL?usp=drive_link | P36: Mining Company | Q36: Embalse N°1 | R36: 2000 M Ton | S36: 20 años
A37: D036 | B37: Firma del EoR e Ingeniero responsable | C37: Registro | D37: GA-DOC-01-2024 | E37: =IF(AND(L37>0,L37<>"-"),"Rev0",IF(AND(K37>0,K37<>"-"),"RevB",IF(AND(J37>0,J37<>"-"),"RevA",IF(AND(I37>0,I37<>"-"),"Iniciado","No Asignado")))) -> No Asignado | F37: {=_xlfn.IFS(E37="No Asignado",0,E37="Iniciado",0.2,E37="RevA",0.4,E37="RevB",0.7,E37="Rev0",1)} -> 0 | G37: Consultor 5 | H37: Operaciones | I37: 0 | J37: - | K37: - | L37: - | M37: 12 | N37: - | O37: https://drive.google.com/drive/folders/1IaEo6qPMz_Vb8OOQY3e1RIre4Fj4qXZL?usp=drive_link | P37: Mining Company | Q37: Embalse N°1 | R37: 2000 M Ton | S37: 20 años
A38: D037 | B38: Política de Relaves | C38: Política | D38: GA-DOC-01-2024 | E38: =IF(AND(L38>0,L38<>"-"),"Rev0",IF(AND(K38>0,K38<>"-"),"RevB",IF(AND(J38>0,J38<>"-"),"RevA",IF(AND(I38>0,I38<>"-"),"Iniciado","No Asignado")))) -> No Asignado | F38: {=_xlfn.IFS(E38="No Asignado",0,E38="Iniciado",0.2,E38="RevA",0.4,E38="RevB",0.7,E38="Rev0",1)} -> 0 | G38: Consultor 5 | H38: Operaciones | I38: 0 | J38: - | K38: - | L38: - | M38: 36 | N38: - | O38: https://drive.google.com/drive/folders/1IaEo6qPMz_Vb8OOQY3e1RIre4Fj4qXZL?usp=drive_link | P38: Mining Company | Q38: Embalse N°1 | R38: 2000 M Ton | S38: 20 años
A39: D038 | B39: Procedimiento de Pago de Incentivos | C39: Procedimiento | D39: GA-DOC-01-2024 | E39: =IF(AND(L39>0,L39<>"-"),"Rev0",IF(AND(K39>0,K39<>"-"),"RevB",IF(AND(J39>0,J39<>"-"),"RevA",IF(AND(I39>0,I39<>"-"),"Iniciado","No Asignado")))) -> No Asignado | F39: {=_xlfn.IFS(E39="No Asignado",0,E39="Iniciado",0.2,E39="RevA",0.4,E39="RevB",0.7,E39="Rev0",1)} -> 0 | G39: Consultor 5 | H39: Operaciones | I39: 0 | J39: - | K39: - | L39: - | M39: 6 | N39: - | O39: https://drive.google.com/drive/folders/1IaEo6qPMz_Vb8OOQY3e1RIre4Fj4qXZL?usp=drive_link | P39: Mining Company | Q39: Embalse N°1 | R39: 2000 M Ton | S39: 20 años
A40: D039 | B40: Manual de Roles y Responsabilidades | C40: Manual | D40: GA-DOC-01-2024 | E40: =IF(AND(L40>0,L40<>"-"),"Rev0",IF(AND(K40>0,K40<>"-"),"RevB",IF(AND(J40>0,J40<>"-"),"RevA",IF(AND(I40>0,I40<>"-"),"Iniciado","No Asignado")))) -> Iniciado | F40: {=_xlfn.IFS(E40="No Asignado",0,E40="Iniciado",0.2,E40="RevA",0.4,E40="RevB",0.7,E40="Rev0",1)} -> 0.2 | G40: Consultor 5 | H40: Operaciones | I40: 45347 | J40: - | K40: - | L40: - | M40: 12 | N40: - | O40: https://drive.google.com/drive/folders/1IaEo6qPMz_Vb8OOQY3e1RIre4Fj4qXZL?usp=drive_link | P40: Mining Company | Q40: Embalse N°1 | R40: 2000 M Ton | S40: 20 años
...

Sheet Criterios GISTM
A1: ID_Criterio | B1: Tema | C1: Nombre Tema | D1: Principio | E1: Descripción Principio | F1: Requisito | G1: Descripción Requisito | H1: Criterio | I1: Descripción Criterio | J1: Ponderación
A2: C001 | B2: I | C2: COMUNIDADES AFECTADAS | D2: Principio 01 | E2: Respetar los derechos de las personas afectadas por el proyecto y lograr su participación significativa en todas las fases del ciclo de vida de las instalaciones de relaves, incluido su cierre. | F2: Requisito 01.1 | G2: Requisito 01.1 Demostrar respeto por los derechos humanos en cumplimiento con los Principios Guía de las Naciones Unidas sobre Empresas, realizar la debida diligencia de los derechos humanos para informar las decisiones de gestión a lo largo del ciclo de vida de la instalación de relaves y abordar los riesgos de los derechos humanos en los escenarios de falla creíbles en la instalación de relaves. Para las instalaciones existentes, el Operador puede optar inicialmente por priorizar las cuestiones de los derechos humanos más importantes de acuerdo al UNGP. | H2: 1.1 - A | I2: 1.1 - A El Operador tiene una política de compromiso para respetar los derechos humanos de acuerdo al UNGP. | J2: =1/3 -> 0.33333333 | L2: 1
A3: C002 | B3: I | C3: COMUNIDADES AFECTADAS | D3: Principio 01 | E3: Respetar los derechos de las personas afectadas por el proyecto y lograr su participación significativa en todas las fases del ciclo de vida de las instalaciones de relaves, incluido su cierre. | F3: Requisito 01.1 | G3: Requisito 01.1 Demostrar respeto por los derechos humanos en cumplimiento con los Principios Guía de las Naciones Unidas sobre Empresas, realizar la debida diligencia de los derechos humanos para informar las decisiones de gestión a lo largo del ciclo de vida de la instalación de relaves y abordar los riesgos de los derechos humanos en los escenarios de falla creíbles en la instalación de relaves. Para las instalaciones existentes, el Operador puede optar inicialmente por priorizar las cuestiones de los derechos humanos más importantes de acuerdo al UNGP. | H3: 1.1 - B | I3: 1.1 - B El Operador ha realizado el proceso de diligencias de derechos humanos específicas al sitio para informarlas decisiones de gestión a través del ciclo de vida de los relaves. | J3: =1/3 -> 0.33333333 | L3: 1
A4: C003 | B4: I | C4: COMUNIDADES AFECTADAS | D4: Principio 01 | E4: Respetar los derechos de las personas afectadas por el proyecto y lograr su participación significativa en todas las fases del ciclo de vida de las instalaciones de relaves, incluido su cierre. | F4: Requisito 01.1 | G4: Requisito 01.1 Demostrar respeto por los derechos humanos en cumplimiento con los Principios Guía de las Naciones Unidas sobre Empresas, realizar la debida diligencia de los derechos humanos para informar las decisiones de gestión a lo largo del ciclo de vida de la instalación de relaves y abordar los riesgos de los derechos humanos en los escenarios de falla creíbles en la instalación de relaves. Para las instalaciones existentes, el Operador puede optar inicialmente por priorizar las cuestiones de los derechos humanos más importantes de acuerdo al UNGP. | H4: 1.1 - C | I4: 1.1 - C El Operador ha abordado los riesgos a los derechos humanos de los escenarios de falla creíbles de la instalación de relaves donde aquellos escenarios existan para tal instalación. | J4: =1/3 -> 0.33333333 | L4: 1
A5: C004 | B5: I | C5: COMUNIDADES AFECTADAS | D5: Principio 01 | E5: Respetar los derechos de las personas afectadas por el proyecto y lograr su participación significativa en todas las fases del ciclo de vida de las instalaciones de relaves, incluido su cierre. | F5: Requisito 01.2 | G5: Requisito 01.2 Donde una nueva instalación de relaves puede impactar los derechos de pueblos indígenas o tribales, incluida sus tierras y derechos a los recursos y su derecho a la libre determinación, trabajar para obtener y mantener un Consentimiento Libre, Previo e Informado (CLPI) al demostrar conformidad con la guía internacional y con el marco de las mejores prácticas reconocidas. | H5: 1.2 - A | I5: 1.2 - A El Operador ha identificado los grupos indígenas o tribales que puedan verse afectados por una nueva instalación de relaves, y entiende como los derechos de estas personas pueden verse impactados, incluyendo sus tierras y derechos a los recursos y su derecho a la libre determinación. | J5: =1/2 -> 0.5 | L5: 1
A6: C005 | B6: I | C6: COMUNIDADES AFECTADAS | D6: Principio 01 | E6: Respetar los derechos de las personas afectadas por el proyecto y lograr su participación significativa en todas las fases del ciclo de vida de las instalaciones de relaves, incluido su cierre. | F6: Requisito 01.2 | G6: Requisito 01.2 Donde una nueva instalación de relaves puede impactar los derechos de pueblos indígenas o tribales, incluida sus tierras y derechos a los recursos y su derecho a la libre determinación, trabajar para obtener y mantener un Consentimiento Libre, Previo e Informado (CLPI) al demostrar conformidad con la guía internacional y con el marco de las mejores prácticas reconocidas. | H6: 1.2 - B | I6: 1.2 - B El Operador trabaja para obtener y mantener el CLPI por parte de los grupos indígenas o tribales, en cumplimiento con la guía internacional y marco de las mejores prácticas reconocidas. | J6: =1/2 -> 0.5 | L6: 1
A7: C006 | B7: I | C7: COMUNIDADES AFECTADAS | D7: Principio 01 | E7: Respetar los derechos de las personas afectadas por el proyecto y lograr su participación significativa en todas las fases del ciclo de vida de las instalaciones de relaves, incluido su cierre. | F7: Requisito 01.3 | G7: Requisito 01.3 Demostrar que las personas afectadas por el proyecto participan de forma significativa a lo largo del ciclo de vida de la instalación de relaves en la construcción de la base de conocimientos que puedan influir en la seguridad pública e integridad de la instalación de relaves. El Operador deberá compartir información para respaldar este proceso | H7: 1.3 - A | I7: 1.3 - A El Operador ha identificado a los grupos afectados por el proyecto. | J7: =1/2 -> 0.5 | L7: 1
A8: C007 | B8: I | C8: COMUNIDADES AFECTADAS | D8: Principio 01 | E8: Respetar los derechos de las personas afectadas por el proyecto y lograr su participación significativa en todas las fases del ciclo de vida de las instalaciones de relaves, incluido su cierre. | F8: Requisito 01.3 | G8: Requisito 01.3 Demostrar que las personas afectadas por el proyecto participan de forma significativa a lo largo del ciclo de vida de la instalación de relaves en la construcción de la base de conocimientos que puedan influir en la seguridad pública e integridad de la instalación de relaves. El Operador deberá compartir información para respaldar este proceso | H8: 1.3 - B | I8: 1.3 - B El Operador ha asumido un compromiso significativo con los grupos afectados por el proyecto a través del ciclo de vida de la instalación de relaves para: - Compartir información relevante y accesible sobre la instalación de relaves; - Construir la base de conocimientos para la instalación de relaves, incluyendo el contexto social, medioambiental y económico local; y, - Buscar retroalimentación en las decisiones que pueden tener relación con la seguridad pública y la integridad de la instalación de relaves. | J8: =1/2 -> 0.5 | L8: 1
A9: C008 | B9: I | C9: COMUNIDADES AFECTADAS | D9: Principio 01 | E9: Respetar los derechos de las personas afectadas por el proyecto y lograr su participación significativa en todas las fases del ciclo de vida de las instalaciones de relaves, incluido su cierre. | F9: Requisito 01.4 | G9: Requisito 01.4 Establecer un mecanismo de reclamos no judicial eficaz a nivel operativo que aborde las quejas y agravios de las personas afectadas por el proyecto relacionado a la instalación de relaves, y proporcionar una solución acorde al UNGP | H9: 1.4 - A | I9: 1.4 - A Se desarrolló e implementó un mecanismo de reclamos accesible y eficaz a nivel operativo para personas afectadas por el proyecto. | J9: =1/3 -> 0.33333333 | L9: 1
A10: C009 | B10: I | C10: COMUNIDADES AFECTADAS | D10: Principio 01 | E10: Respetar los derechos de las personas afectadas por el proyecto y lograr su participación significativa en todas las fases del ciclo de vida de las instalaciones de relaves, incluido su cierre. | F10: Requisito 01.5 | G10: Requisito 01.5 Establecer un mecanismo de reclamos no judicial eficaz a nivel operativo que aborde las quejas y agravios de las personas afectadas por el proyecto relacionado a la instalación de relaves, y proporcionar una solución acorde al UNGP | H10: 1.4 - B | I10: 1.4 - B El mecanismo de reclamos abarca quejas y agravios de las personas afectadas por el proyecto relacionado a la instalación de relaves. | J10: =1/3 -> 0.33333333 | L10: 1
A11: C010 | B11: I | C11: COMUNIDADES AFECTADAS | D11: Principio 01 | E11: Respetar los derechos de las personas afectadas por el proyecto y lograr su participación significativa en todas las fases del ciclo de vida de las instalaciones de relaves, incluido su cierre. | F11: Requisito 01.5 | G11: Requisito 01.5 Establecer un mecanismo de reclamos no judicial eficaz a nivel operativo que aborde las quejas y agravios de las personas afectadas por el proyecto relacionado a la instalación de relaves, y proporcionar una solución acorde al UNGP | H11: 1.4 - C | I11: 1.4 - C El mecanismo de reclamos brinda soluciones de acuerdo a las UNGPs 29-31. | J11: =1/3 -> 0.33333333 | L11: 1
A12: C011 | B12: II | C12: BASE DE CONOCIMIENTOS INTEGRADA | D12: Principio 02 | E12: Elaborar y mantener una base de conocimientos interdisciplinaria para respaldar la gestión de los relaves durante todo su ciclo de vida, incluido su cierre. | F12: Requisito 02.1 | G12: Requisito 02.1 Desarrollar y documentar conocimientos sobre el contexto social, medioambiental y económico local de la instalación de relaves, utilizando métodos alineados con las mejores prácticas internacionales. Actualizar este conocimiento por lo menos cada cinco años, y cada vez haya un cambio material, ya sea en la instalación este conocimiento por lo menos cada cinco años, y cada vez haya un cambio material, ya sea en la instalación de relaves o en el contexto social, medioambiental o económico local. Este conocimiento debe capturar las incertidumbres debidas al cambio climático. | H12: 2.1 - A | I12: 2.1 - A El Operador ha documentado el contexto social, medioambiental y económico específico del sitio con respecto a su instalación de relaves. | J12: =1/3 -> 0.33333333 | L12: 2
A13: C012 | B13: II | C13: BASE DE CONOCIMIENTOS INTEGRADA | D13: Principio 02 | E13: Elaborar y mantener una base de conocimientos interdisciplinaria para respaldar la gestión de los relaves durante todo su ciclo de vida, incluido su cierre. | F13: Requisito 02.1 | G13: Requisito 02.1 Desarrollar y documentar conocimientos sobre el contexto social, medioambiental y económico local de la instalación de relaves, utilizando métodos alineados con las mejores prácticas internacionales. Actualizar este conocimiento por lo menos cada cinco años, y cada vez haya un cambio material, ya sea en la instalación este conocimiento por lo menos cada cinco años, y cada vez haya un cambio material, ya sea en la instalación de relaves o en el contexto social, medioambiental o económico local. Este conocimiento debe capturar las incertidumbres debidas al cambio climático. | H13: 2.1 - B | I13: 2.1 - B Evalúa las incertidumbres asociadas s al cambio climático que pueda impactar la seguridad de la instalación de relaves (véase también requisito GISTM 3.1) | J13: =1/3 -> 0.33333333 | L13: 2
A14: C013 | B14: II | C14: BASE DE CONOCIMIENTOS INTEGRADA | D14: Principio 02 | E14: Elaborar y mantener una base de conocimientos interdisciplinaria para respaldar la gestión de los relaves durante todo su ciclo de vida, incluido su cierre. | F14: Requisito 02.1 | G14: Requisito 02.1 Desarrollar y documentar conocimientos sobre el contexto social, medioambiental y económico local de la instalación de relaves, utilizando métodos alineados con las mejores prácticas internacionales. Actualizar este conocimiento por lo menos cada cinco años, y cada vez haya un cambio material, ya sea en la instalación este conocimiento por lo menos cada cinco años, y cada vez haya un cambio material, ya sea en la instalación de relaves o en el contexto social, medioambiental o económico local. Este conocimiento debe capturar las incertidumbres debidas al cambio climático. | H14: 2.1 - C | I14: 2.1 - C El Operador actualiza la información descrita arriba en un intervalo de por lo menos cinco años, y cada vez que haya un cambio material en la instalación de relaves o relacionado al contexto ambiental, social o económico. | J14: =1/3 -> 0.33333333 | L14: 2
A15: C014 | B15: II | C15: BASE DE CONOCIMIENTOS INTEGRADA | D15: Principio 02 | E15: Elaborar y mantener una base de conocimientos interdisciplinaria para respaldar la gestión de los relaves durante todo su ciclo de vida, incluido su cierre. | F15: Requisito 02.2 | G15: Requisito 02.2 Preparar, documentar y actualizar una caracterización del sitio detallada de la (las) instalación(es) de relaves que incluyan datos sobre el clima, geomorfología, geología, geoquímica, hidrología e hidrogeología (flujo y calidad de aguas superficiales y de subsuelo), geotécnicos y sísmicos. Las propiedades químicas y físicas del relave serán caracterizadas y actualizadas con regularidad para tomar en cuenta la variabilidad de las propiedades y procesamiento del mineral | H15: 2.2 - A | I15: 2.2 - A Existe una caracterización detallada1 del(los) sitio(s) de la instalación de relaves y se actualiza según se justifica a través del ciclo de vida, para reflejar los cambios materiales en las condiciones y nuevos conocimientos. | J15: =1/3 -> 0.33333333 | L15: 2
A16: C015 | B16: II | C16: BASE DE CONOCIMIENTOS INTEGRADA | D16: Principio 02 | E16: Elaborar y mantener una base de conocimientos interdisciplinaria para respaldar la gestión de los relaves durante todo su ciclo de vida, incluido su cierre. | F16: Requisito 02.2 | G16: Requisito 02.2 Preparar, documentar y actualizar una caracterización del sitio detallada de la (las) instalación(es) de relaves que incluyan datos sobre el clima, geomorfología, geología, geoquímica, hidrología e hidrogeología (flujo y calidad de aguas superficiales y de subsuelo), geotécnicos y sísmicos. Las propiedades químicas y físicas del relave serán caracterizadas y actualizadas con regularidad para tomar en cuenta la variabilidad de las propiedades y procesamiento del mineral | H16: 2.2 - B | I16: 2.2 - B La caracterización del sitio es respaldada por datos incluyendo datos en clima, geomorfología, geología, geoquímica, hidrología, hidrogeología (flujo y calidad de aguas superficiales y subsuelo), geotécnicos y sísmicos). | J16: =1/3 -> 0.33333333 | L16: 2
A17: C016 | B17: II | C17: BASE DE CONOCIMIENTOS INTEGRADA | D17: Principio 02 | E17: Elaborar y mantener una base de conocimientos interdisciplinaria para respaldar la gestión de los relaves durante todo su ciclo de vida, incluido su cierre. | F17: Requisito 02.2 | G17: Requisito 02.2 Preparar, documentar y actualizar una caracterización del sitio detallada de la (las) instalación(es) de relaves que incluyan datos sobre el clima, geomorfología, geología, geoquímica, hidrología e hidrogeología (flujo y calidad de aguas superficiales y de subsuelo), geotécnicos y sísmicos. Las propiedades químicas y físicas del relave serán caracterizadas y actualizadas con regularidad para tomar en cuenta la variabilidad de las propiedades y procesamiento del mineral | H17: 2.2 - C | I17: 2.2 - C Existe una caracterización de relaves, considerando las propiedades físicas y geoquímicas, y se actualizan a lo largo del ciclo de vida para tomar en cuenta la variabilidad en las propiedades y el procesamiento del mineral y la deposición de relaves. | J17: =1/3 -> 0.33333333 | L17: 2
A18: C017 | B18: II | C18: BASE DE CONOCIMIENTOS INTEGRADA | D18: Principio 02 | E18: Elaborar y mantener una base de conocimientos interdisciplinaria para respaldar la gestión de los relaves durante todo su ciclo de vida, incluido su cierre. | F18: Requisito 02.3 | G18: Requisito 02.3 Desarrollar y documentar un análisis de brechas para la instalación de relaves, utilizando una metodología que considere modelos de falla creíble, condiciones del sitio, y las propiedades de las lamas. Los resultados del análisis estimarán el área física impactada por una falla potencial. Cuando materiales fluidos (agua o sólidos licuables) estén presentes en una instalación de relaves con una Clasificación de Consecuencias "Altas", "Muy Altas" o "Extremas", los resultados deben incluir estimados del área física impactada por la falla potencial, tiempos de llegada de flujo, profundidad y velocidades, y profundidad de la deposición de material. Actualizar cuando se dé un cambio material, ya sea a la instalación de relaves o al área física impactada. | H18: 2.3 - A | I18: 2.3 - A Donde una instalación de relaves tiene un modelo/escenario de falla creíble1, hay un análisis de brecha documentado para la instalación de relaves, utilizando una metodología que considere los modelos de falla creíbles, condiciones del sitio y propiedades de los relaves. | J18: =1/4 -> 0.25 | L18: 3
A19: C018 | B19: II | C19: BASE DE CONOCIMIENTOS INTEGRADA | D19: Principio 02 | E19: Elaborar y mantener una base de conocimientos interdisciplinaria para respaldar la gestión de los relaves durante todo su ciclo de vida, incluido su cierre. | F19: Requisito 02.3 | G19: Requisito 02.3 Desarrollar y documentar un análisis de brechas para la instalación de relaves, utilizando una metodología que considere modelos de falla creíble, condiciones del sitio, y las propiedades de las lamas. Los resultados del análisis estimarán el área física impactada por una falla potencial. Cuando materiales fluidos (agua o sólidos licuables) estén presentes en una instalación de relaves con una Clasificación de Consecuencias "Altas", "Muy Altas" o "Extremas", los resultados deben incluir estimados del área física impactada por la falla potencial, tiempos de llegada de flujo, profundidad y velocidades, y profundidad de la deposición de material. Actualizar cuando se dé un cambio material, ya sea a la instalación de relaves o al área física impactada. | H19: 2.3 - B | I19: 2.3 - B El área física potencialmente afectada por una falla es estimada y definida. | J19: =1/4 -> 0.25 | L19: 3
A20: C019 | B20: II | C20: BASE DE CONOCIMIENTOS INTEGRADA | D20: Principio 02 | E20: Elaborar y mantener una base de conocimientos interdisciplinaria para respaldar la gestión de los relaves durante todo su ciclo de vida, incluido su cierre. | F20: Requisito 02.3 | G20: Requisito 02.3 Desarrollar y documentar un análisis de brechas para la instalación de relaves, utilizando una metodología que considere modelos de falla creíble, condiciones del sitio, y las propiedades de las lamas. Los resultados del análisis estimarán el área física impactada por una falla potencial. Cuando materiales fluidos (agua o sólidos licuables) estén presentes en una instalación de relaves con una Clasificación de Consecuencias "Altas", "Muy Altas" o "Extremas", los resultados deben incluir estimados del área física impactada por la falla potencial, tiempos de llegada de flujo, profundidad y velocidades, y profundidad de la deposición de material. Actualizar cuando se dé un cambio material, ya sea a la instalación de relaves o al área física impactada. | H20: 2.3 - C | I20: 2.3 - C Para las instalaciones con escenarios de falla creíbles involucrando materiales fluidos (agua y sólidos licuables) y con una clasificación de consecuencias de “Altas”, “Muy Altas” o “Extremas”, se estiman los tiempos de llegada de flujo, profundidades de flujo, velocidades de flujo y profundidad del material depositado. | J20: =1/4 -> 0.25 | L20: 3
A21: C020 | B21: II | C21: BASE DE CONOCIMIENTOS INTEGRADA | D21: Principio 02 | E21: Elaborar y mantener una base de conocimientos interdisciplinaria para respaldar la gestión de los relaves durante todo su ciclo de vida, incluido su cierre. | F21: Requisito 02.3 | G21: Requisito 02.3 Desarrollar y documentar un análisis de brechas para la instalación de relaves, utilizando una metodología que considere modelos de falla creíble, condiciones del sitio, y las propiedades de las lamas. Los resultados del análisis estimarán el área física impactada por una falla potencial. Cuando materiales fluidos (agua o sólidos licuables) estén presentes en una instalación de relaves con una Clasificación de Consecuencias "Altas", "Muy Altas" o "Extremas", los resultados deben incluir estimados del área física impactada por la falla potencial, tiempos de llegada de flujo, profundidad y velocidades, y profundidad de la deposición de material. Actualizar cuando se dé un cambio material, ya sea a la instalación de relaves o al área física impactada. | H21: 2.3 - D | I21: 2.3 - D Para las instalaciones que cumplen con las condiciones a, b y c, el análisis de brecha se completa/ actualiza si se da un cambio material 1 en la instalación de relaves o a la base de conocimientos que resulte en un escenario de falla creíble que pueda llevar a una falla de flujo. | J21: =1/4 -> 0.25 | L21: 3
A22: C021 | B22: II | C22: BASE DE CONOCIMIENTOS INTEGRADA | D22: Principio 02 | E22: Elaborar y mantener una base de conocimientos interdisciplinaria para respaldar la gestión de los relaves durante todo su ciclo de vida, incluido su cierre. | F22: Requisito 02.4 | G22: Requisito 02.4 Para poder identificar los grupos de mayor riesgo, referirse al análisis de brechas actualizado de la instalación de relaves para evaluar y documentar la exposición y vulnerabilidad humana a los escenarios de falla creíble de la instalación de relaves. Actualizar la evaluación cuando se dé un cambio material, ya sea en la instalación de relaves o en la base del conocimiento | H22: 2.4 - A | I22: 2.4 - A Se identifican los grupos de mayor riesgo, considerando el análisis de brechas para aquellas instalaciones con escenarios de fallas creíbles según el Requisito 2.3. | J22: =1/3 -> 0.33333333 | L22: 3
A23: C022 | B23: II | C23: BASE DE CONOCIMIENTOS INTEGRADA | D23: Principio 02 | E23: Elaborar y mantener una base de conocimientos interdisciplinaria para respaldar la gestión de los relaves durante todo su ciclo de vida, incluido su cierre. | F23: Requisito 02.4 | G23: Requisito 02.4 Para poder identificar los grupos de mayor riesgo, referirse al análisis de brechas actualizado de la instalación de relaves para evaluar y documentar la exposición y vulnerabilidad humana a los escenarios de falla creíble de la instalación de relaves. Actualizar la evaluación cuando se dé un cambio material, ya sea en la instalación de relaves o en la base del conocimiento | H23: 2.4 - B | I23: 2.4 - B Se documenta la exposición y vulnerabilidad humana potencial de los escenarios de fallas creíbles de la instalación de relaves. | J23: =1/3 -> 0.33333333 | L23: 3
A24: C023 | B24: II | C24: BASE DE CONOCIMIENTOS INTEGRADA | D24: Principio 02 | E24: Elaborar y mantener una base de conocimientos interdisciplinaria para respaldar la gestión de los relaves durante todo su ciclo de vida, incluido su cierre. | F24: Requisito 02.4 | G24: Requisito 02.4 Para poder identificar los grupos de mayor riesgo, referirse al análisis de brechas actualizado de la instalación de relaves para evaluar y documentar la exposición y vulnerabilidad humana a los escenarios de falla creíble de la instalación de relaves. Actualizar la evaluación cuando se dé un cambio material, ya sea en la instalación de relaves o en la base del conocimiento | H24: 2.4 - C | I24: 2.4 - C La evaluación de la exposición y vulnerabilidad humana se actualiza si es que se da un cambio material 1 a la credibilidad de la falla de flujo potencial y su correspondiente análisis de brecha o base del conocimiento. | J24: =1/3 -> 0.33333333 | L24: 3
A25: C024 | B25: II | C25: BASE DE CONOCIMIENTOS INTEGRADA | D25: Principio 03 | E25: Utilizar los elementos de la base de conocimientos – sociales, ambientales, de la economía local y técnicos – con el fin de informar las decisiones durante el ciclo de vida de la instalación de relaves, incluido su cierre | F25: Requisito 03.1 | G25: Requisito 03.1 Para mejorar la resistencia al cambio climático, evaluar, actualizar con regularidad y utilizar conocimientos del cambio climático a través del ciclo de vida de la instalación de relaves de acuerdo a los principios de la Gestión Adaptativa. | H25: 3.1 - A | I25: 3.1 - A Para mejorar la resistencia, se actualiza con regularidad el conocimiento sobre el cambio climático y se usa para evaluar los riesgos y oportunidades para el ciclo de vida de la instalación de relaves, en cumplimiento con los principios de gestión adaptativa, con la meta de mejorar la resistencia al cambio climático. | J25: 1 | L25: 2
A26: C025 | B26: II | C26: BASE DE CONOCIMIENTOS INTEGRADA | D26: Principio 03 | E26: Utilizar los elementos de la base de conocimientos – sociales, ambientales, de la economía local y técnicos – con el fin de informar las decisiones durante el ciclo de vida de la instalación de relaves, incluido su cierre | F26: Requisito 03.2 | G26: Requisito 03.2 Para nuevas instalaciones de relaves, el Operador deberá utilizar la base de conocimientos y realizará un análisis de alternativas de criterio múltiple de todos los sitios, tecnologías y estrategias factibles para la gestión de relaves. El objetivo de este análisis será de: (i) seleccionar una alternativa que minimice los riesgos a las personas y medioambiente durante el ciclo de vida de la instalación de relaves, y (ii) minimiza el volumen de aguas y relaves colocados en instalaciones de relaves externas. Este análisis será un análisis objetivo de restricciones que será revisado por la Junta de Revisión Independiente de Relaves (ITRB) o un revisor técnico superior independiente. Para las instalaciones de relaves existentes, el Operador deberá revisar y refinar periódicamente las tecnologías y diseños de relaves, y las estrategias de gestión para minimizar riesgos y mejorar resultados medioambientales. Se aplicaría una excepción a las instalaciones que se demuestren estar en un estado de cierre seguro. | H26: 3.2 - A | I26: 3.2 A Para las nuevas instalaciones de relaves, un Análisis de Alternativas1 se realiza para examinar sitios, tecnologías y estrategias factibles para el tratamiento de relaves durante el ciclo de vida, que busca minimizar: - riesgos a las personas y medio ambiente; - volumen de relaves y aguas almacenados en instalaciones superficiales. | J26: =1/3 -> 0.33333333 | L26: 1
A27: C026 | B27: II | C27: BASE DE CONOCIMIENTOS INTEGRADA | D27: Principio 03 | E27: Utilizar los elementos de la base de conocimientos – sociales, ambientales, de la economía local y técnicos – con el fin de informar las decisiones durante el ciclo de vida de la instalación de relaves, incluido su cierre | F27: Requisito 03.2 | G27: Requisito 03.2 Para nuevas instalaciones de relaves, el Operador deberá utilizar la base de conocimientos y realizará un análisis de alternativas de criterio múltiple de todos los sitios, tecnologías y estrategias factibles para la gestión de relaves. El objetivo de este análisis será de: (i) seleccionar una alternativa que minimice los riesgos a las personas y medioambiente durante el ciclo de vida de la instalación de relaves, y (ii) minimiza el volumen de aguas y relaves colocados en instalaciones de relaves externas. Este análisis será un análisis objetivo de restricciones que será revisado por la Junta de Revisión Independiente de Relaves (ITRB) o un revisor técnico superior independiente. Para las instalaciones de relaves existentes, el Operador deberá revisar y refinar periódicamente las tecnologías y diseños de relaves, y las estrategias de gestión para minimizar riesgos y mejorar resultados medioambientales. Se aplicaría una excepción a las instalaciones que se demuestren estar en un estado de cierre seguro. | H27: 3.2 - B | I27: 3.2 B Para instalaciones existentes que no estén en un estado de cierre seguro, hay revisiones periódicas de las tecnologías, diseños y estrategias de tratamiento de relaves, y evaluaciones del potencial para implementar mejoras que surjan de las revisiones. | J27: =1/3 -> 0.33333333 | L27: 1
A28: C027 | B28: II | C28: BASE DE CONOCIMIENTOS INTEGRADA | D28: Principio 03 | E28: Utilizar los elementos de la base de conocimientos – sociales, ambientales, de la economía local y técnicos – con el fin de informar las decisiones durante el ciclo de vida de la instalación de relaves, incluido su cierre | F28: Requisito 03.2 | G28: Requisito 03.2 Para nuevas instalaciones de relaves, el Operador deberá utilizar la base de conocimientos y realizará un análisis de alternativas de criterio múltiple de todos los sitios, tecnologías y estrategias factibles para la gestión de relaves. El objetivo de este análisis será de: (i) seleccionar una alternativa que minimice los riesgos a las personas y medioambiente durante el ciclo de vida de la instalación de relaves, y (ii) minimiza el volumen de aguas y relaves colocados en instalaciones de relaves externas. Este análisis será un análisis objetivo de restricciones que será revisado por la Junta de Revisión Independiente de Relaves (ITRB) o un revisor técnico superior independiente. Para las instalaciones de relaves existentes, el Operador deberá revisar y refinar periódicamente las tecnologías y diseños de relaves, y las estrategias de gestión para minimizar riesgos y mejorar resultados medioambientales. Se aplicaría una excepción a las instalaciones que se demuestren estar en un estado de cierre seguro. | H28: 3.2 - C | I28: 3.2 C Para las nuevas instalaciones, el análisis es revisado por el ITRB o un revisor técnico superior independiente. | J28: =1/3 -> 0.33333333 | L28: 1
A29: C028 | B29: II | C29: BASE DE CONOCIMIENTOS INTEGRADA | D29: Principio 03 | E29: Utilizar los elementos de la base de conocimientos – sociales, ambientales, de la economía local y técnicos – con el fin de informar las decisiones durante el ciclo de vida de la instalación de relaves, incluido su cierre | F29: Requisito 03.3 | G29: Requisito 03.3 Para las nuevas instalaciones de relaves, utilizar la base de conocimientos, incluyendo la incertidumbre debida al cambio climático para evaluar los impactos sociales, medioambientales y económicos locales de la instalación de relaves y su falla potencial a lo largo de su ciclo de vida. Donde las evaluaciones de impacto predicen impactos materiales agudos o crónicos, el Operador deberá desarrollar, documentar e implementar planes de mitigación y gestión usando la jerarquía de mitigación. | H29: 3.3 - A | I29: 3.3 - A Se realizan las evaluaciones de impacto medioambiental, social y económico locales y se informan a la base de conocimiento existente. | J29: =1/4 -> 0.25 | L29: 2
A30: C029 | B30: II | C30: BASE DE CONOCIMIENTOS INTEGRADA | D30: Principio 03 | E30: Utilizar los elementos de la base de conocimientos – sociales, ambientales, de la economía local y técnicos – con el fin de informar las decisiones durante el ciclo de vida de la instalación de relaves, incluido su cierre | F30: Requisito 03.3 | G30: Requisito 03.3 Para las nuevas instalaciones de relaves, utilizar la base de conocimientos, incluyendo la incertidumbre debida al cambio climático para evaluar los impactos sociales, medioambientales y económicos locales de la instalación de relaves y su falla potencial a lo largo de su ciclo de vida. Donde las evaluaciones de impacto predicen impactos materiales agudos o crónicos, el Operador deberá desarrollar, documentar e implementar planes de mitigación y gestión usando la jerarquía de mitigación. | H30: 3.3 - B | I30: 3.3 - B Las evaluaciones ambientales, sociales y económico locales demuestran que las incertidumbres son consideradas en la evaluación de la vida de los impactos de las instalaciones de relaves y si hay algún potencial para una falla creíble a lo largo del ciclo de vida de la instalación de relaves. | J30: =1/4 -> 0.25 | L30: 2
A31: C030 | B31: II | C31: BASE DE CONOCIMIENTOS INTEGRADA | D31: Principio 03 | E31: Utilizar los elementos de la base de conocimientos – sociales, ambientales, de la economía local y técnicos – con el fin de informar las decisiones durante el ciclo de vida de la instalación de relaves, incluido su cierre | F31: Requisito 03.3 | G31: Requisito 03.3 Para las nuevas instalaciones de relaves, utilizar la base de conocimientos, incluyendo la incertidumbre debida al cambio climático para evaluar los impactos sociales, medioambientales y económicos locales de la instalación de relaves y su falla potencial a lo largo de su ciclo de vida. Donde las evaluaciones de impacto predicen impactos materiales agudos o crónicos, el Operador deberá desarrollar, documentar e implementar planes de mitigación y gestión usando la jerarquía de mitigación. | H31: 3.3 - C | I31: 3.3 - C Medidas y planes de mitigación y gestión son desarrollados, documentados e implementados para abarcar los impactos materiales crónicos y agudos. | J31: =1/4 -> 0.25 | L31: 2
