Workbook

Sheet Criterios GISTM
A1: ID_Criterio | B1: Tema | C1: Nombre Tema | D1: Principio | E1: Descripción Principio | F1: Requisito | G1: Descripción Requisito | H1: Criterio | I1: Descripción Criterio | J1: Ponderación
A2: C001 | B2: I | C2: COMUNIDADES AFECTADAS | D2: Principio 01 | E2: Respetar los derechos de las personas afectadas por el proyecto y lograr su participación significativa en todas las fases del ciclo de vida de las instalaciones de relaves, incluido su cierre. | F2: Requisito 01.1 | G2: Requisito 01.1 Demostrar respeto por los derechos humanos en cumplimiento con los Principios Guía de las Naciones Unidas sobre Empresas, realizar la debida diligencia de los derechos humanos para informar las decisiones de gestión a lo largo del ciclo de vida de la instalación de relaves y abordar los riesgos de los derechos humanos en los escenarios de falla creíbles en la instalación de relaves. Para las instalaciones existentes, el Operador puede optar inicialmente por priorizar las cuestiones de los derechos humanos más importantes de acuerdo al UNGP. | H2: 1.1 - A | I2: 1.1 - A El Operador tiene una política de compromiso para respetar los derechos humanos de acuerdo al UNGP. | J2: =1/3 -> 0.33333333
A3: C002 | B3: I | C3: COMUNIDADES AFECTADAS | D3: Principio 01 | E3: Respetar los derechos de las personas afectadas por el proyecto y lograr su participación significativa en todas las fases del ciclo de vida de las instalaciones de relaves, incluido su cierre. | F3: Requisito 01.1 | G3: Requisito 01.1 Demostrar respeto por los derechos humanos en cumplimiento con los Principios Guía de las Naciones Unidas sobre Empresas, realizar la debida diligencia de los derechos humanos para informar las decisiones de gestión a lo largo del ciclo de vida de la instalación de relaves y abordar los riesgos de los derechos humanos en los escenarios de falla creíbles en la instalación de relaves. Para las instalaciones existentes, el Operador puede optar inicialmente por priorizar las cuestiones de los derechos humanos más importantes de acuerdo al UNGP. | H3: 1.1 - B | I3: 1.1 - B El Operador ha realizado el proceso de diligencias de derechos humanos específicas al sitio para informarlas decisiones de gestión a través del ciclo de vida de los relaves. | J3: =1/3 -> 0.33333333
A4: C003 | B4: I | C4: COMUNIDADES AFECTADAS | D4: Principio 01 | E4: Respetar los derechos de las personas afectadas por el proyecto y lograr su participación significativa en todas las fases del ciclo de vida de las instalaciones de relaves, incluido su cierre. | F4: Requisito 01.1 | G4: Requisito 01.1 Demostrar respeto por los derechos humanos en cumplimiento con los Principios Guía de las Naciones Unidas sobre Empresas, realizar la debida diligencia de los derechos humanos para informar las decisiones de gestión a lo largo del ciclo de vida de la instalación de relaves y abordar los riesgos de los derechos humanos en los escenarios de falla creíbles en la instalación de relaves. Para las instalaciones existentes, el Operador puede optar inicialmente por priorizar las cuestiones de los derechos humanos más importantes de acuerdo al UNGP. | H4: 1.1 - C | I4: 1.1 - C El Operador ha abordado los riesgos a los derechos humanos de los escenarios de falla creíbles de la instalación de relaves donde aquellos escenarios existan para tal instalación. | J4: =1/3 -> 0.33333333
A5: C004 | B5: I | C5: COMUNIDADES AFECTADAS | D5: Principio 01 | E5: Respetar los derechos de las personas afectadas por el proyecto y lograr su participación significativa en todas las fases del ciclo de vida de las instalaciones de relaves, incluido su cierre. | F5: Requisito 01.2 | G5: Requisito 01.2 Donde una nueva instalación de relaves puede impactar los derechos de pueblos indígenas o tribales, incluida sus tierras y derechos a los recursos y su derecho a la libre determinación, trabajar para obtener y mantener un Consentimiento Libre, Previo e Informado (CLPI) al demostrar conformidad con la guía internacional y con el marco de las mejores prácticas reconocidas. | H5: 1.2 - A | I5: 1.2 - A El Operador ha identificado los grupos indígenas o tribales que puedan verse afectados por una nueva instalación de relaves, y entiende como los derechos de estas personas pueden verse impactados, incluyendo sus tierras y derechos a los recursos y su derecho a la libre determinación. | J5: =1/2 -> 0.5
A6: C005 | B6: I | C6: COMUNIDADES AFECTADAS | D6: Principio 01 | E6: Respetar los derechos de las personas afectadas por el proyecto y lograr su participación significativa en todas las fases del ciclo de vida de las instalaciones de relaves, incluido su cierre. | F6: Requisito 01.2 | G6: Requisito 01.2 Donde una nueva instalación de relaves puede impactar los derechos de pueblos indígenas o tribales, incluida sus tierras y derechos a los recursos y su derecho a la libre determinación, trabajar para obtener y mantener un Consentimiento Libre, Previo e Informado (CLPI) al demostrar conformidad con la guía internacional y con el marco de las mejores prácticas reconocidas. | H6: 1.2 - B | I6: 1.2 - B El Operador trabaja para obtener y mantener el CLPI por parte de los grupos indígenas o tribales, en cumplimiento con la guía internacional y marco de las mejores prácticas reconocidas. | J6: =1/2 -> 0.5
A7: C006 | B7: I | C7: COMUNIDADES AFECTADAS | D7: Principio 01 | E7: Respetar los derechos de las personas afectadas por el proyecto y lograr su participación significativa en todas las fases del ciclo de vida de las instalaciones de relaves, incluido su cierre. | F7: Requisito 01.3 | G7: Requisito 01.3 Demostrar que las personas afectadas por el proyecto participan de forma significativa a lo largo del ciclo de vida de la instalación de relaves en la construcción de la base de conocimientos que puedan influir en la seguridad pública e integridad de la instalación de relaves. El Operador deberá compartir información para respaldar este proceso | H7: 1.3 - A | I7: 1.3 - A El Operador ha identificado a los grupos afectados por el proyecto. | J7: =1/2 -> 0.5
A8: C007 | B8: I | C8: COMUNIDADES AFECTADAS | D8: Principio 01 | E8: Respetar los derechos de las personas afectadas por el proyecto y lograr su participación significativa en todas las fases del ciclo de vida de las instalaciones de relaves, incluido su cierre. | F8: Requisito 01.3 | G8: Requisito 01.3 Demostrar que las personas afectadas por el proyecto participan de forma significativa a lo largo del ciclo de vida de la instalación de relaves en la construcción de la base de conocimientos que puedan influir en la seguridad pública e integridad de la instalación de relaves. El Operador deberá compartir información para respaldar este proceso | H8: 1.3 - B | I8: 1.3 - B El Operador ha asumido un compromiso significativo con los grupos afectados por el proyecto a través del ciclo de vida de la instalación de relaves para: - Compartir información relevante y accesible sobre la instalación de relaves; - Construir la base de conocimientos para la instalación de relaves, incluyendo el contexto social, medioambiental y económico local; y, - Buscar retroalimentación en las decisiones que pueden tener relación con la seguridad pública y la integridad de la instalación de relaves. | J8: =1/2 -> 0.5
A9: C008 | B9: I | C9: COMUNIDADES AFECTADAS | D9: Principio 01 | E9: Respetar los derechos de las personas afectadas por el proyecto y lograr su participación significativa en todas las fases del ciclo de vida de las instalaciones de relaves, incluido su cierre. | F9: Requisito 01.4 | G9: Requisito 01.4 Establecer un mecanismo de reclamos no judicial eficaz a nivel operativo que aborde las quejas y agravios de las personas afectadas por el proyecto relacionado a la instalación de relaves, y proporcionar una solución acorde al UNGP | H9: 1.4 - A | I9: 1.4 - A Se desarrolló e implementó un mecanismo de reclamos accesible y eficaz a nivel operativo para personas afectadas por el proyecto. | J9: =1/3 -> 0.33333333
A10: C009 | B10: I | C10: COMUNIDADES AFECTADAS | D10: Principio 01 | E10: Respetar los derechos de las personas afectadas por el proyecto y lograr su participación significativa en todas las fases del ciclo de vida de las instalaciones de relaves, incluido su cierre. | F10: Requisito 01.5 | G10: Requisito 01.5 Establecer un mecanismo de reclamos no judicial eficaz a nivel operativo que aborde las quejas y agravios de las personas afectadas por el proyecto relacionado a la instalación de relaves, y proporcionar una solución acorde al UNGP | H10: 1.4 - B | I10: 1.4 - B El mecanismo de reclamos abarca quejas y agravios de las personas afectadas por el proyecto relacionado a la instalación de relaves. | J10: =1/3 -> 0.33333333
A11: C010 | B11: I | C11: COMUNIDADES AFECTADAS | D11: Principio 01 | E11: Respetar los derechos de las personas afectadas por el proyecto y lograr su participación significativa en todas las fases del ciclo de vida de las instalaciones de relaves, incluido su cierre. | F11: Requisito 01.5 | G11: Requisito 01.5 Establecer un mecanismo de reclamos no judicial eficaz a nivel operativo que aborde las quejas y agravios de las personas afectadas por el proyecto relacionado a la instalación de relaves, y proporcionar una solución acorde al UNGP | H11: 1.4 - C | I11: 1.4 - C El mecanismo de reclamos brinda soluciones de acuerdo a las UNGPs 29-31. | J11: =1/3 -> 0.33333333
A12: C011 | B12: II | C12: BASE DE CONOCIMIENTOS INTEGRADA | D12: Principio 02 | E12: Elaborar y mantener una base de conocimientos interdisciplinaria para respaldar la gestión de los relaves durante todo su ciclo de vida, incluido su cierre. | F12: Requisito 02.1 | G12: Requisito 02.1 Desarrollar y documentar conocimientos sobre el contexto social, medioambiental y económico local de la instalación de relaves, utilizando métodos alineados con las mejores prácticas internacionales. Actualizar este conocimiento por lo menos cada cinco años, y cada vez haya un cambio material, ya sea en la instalación este conocimiento por lo menos cada cinco años, y cada vez haya un cambio material, ya sea en la instalación de relaves o en el contexto social, medioambiental o económico local. Este conocimiento debe capturar las incertidumbres debidas al cambio climático. | H12: 2.1 - A | I12: 2.1 - A El Operador ha documentado el contexto social, medioambiental y económico específico del sitio con respecto a su instalación de relaves. | J12: =1/3 -> 0.33333333
A13: C012 | B13: II | C13: BASE DE CONOCIMIENTOS INTEGRADA | D13: Principio 02 | E13: Elaborar y mantener una base de conocimientos interdisciplinaria para respaldar la gestión de los relaves durante todo su ciclo de vida, incluido su cierre. | F13: Requisito 02.1 | G13: Requisito 02.1 Desarrollar y documentar conocimientos sobre el contexto social, medioambiental y económico local de la instalación de relaves, utilizando métodos alineados con las mejores prácticas internacionales. Actualizar este conocimiento por lo menos cada cinco años, y cada vez haya un cambio material, ya sea en la instalación este conocimiento por lo menos cada cinco años, y cada vez haya un cambio material, ya sea en la instalación de relaves o en el contexto social, medioambiental o económico local. Este conocimiento debe capturar las incertidumbres debidas al cambio climático. | H13: 2.1 - B | I13: 2.1 - B Evalúa las incertidumbres asociadas s al cambio climático que pueda impactar la seguridad de la instalación de relaves (véase también requisito GISTM 3.1) | J13: =1/3 -> 0.33333333
A14: C013 | B14: II | C14: BASE DE CONOCIMIENTOS INTEGRADA | D14: Principio 02 | E14: Elaborar y mantener una base de conocimientos interdisciplinaria para respaldar la gestión de los relaves durante todo su ciclo de vida, incluido su cierre. | F14: Requisito 02.1 | G14: Requisito 02.1 Desarrollar y documentar conocimientos sobre el contexto social, medioambiental y económico local de la instalación de relaves, utilizando métodos alineados con las mejores prácticas internacionales. Actualizar este conocimiento por lo menos cada cinco años, y cada vez haya un cambio material, ya sea en la instalación este conocimiento por lo menos cada cinco años, y cada vez haya un cambio material, ya sea en la instalación de relaves o en el contexto social, medioambiental o económico local. Este conocimiento debe capturar las incertidumbres debidas al cambio climático. | H14: 2.1 - C | I14: 2.1 - C El Operador actualiza la información descrita arriba en un intervalo de por lo menos cinco años, y cada vez que haya un cambio material en la instalación de relaves o relacionado al contexto ambiental, social o económico. | J14: =1/3 -> 0.33333333
A15: C014 | B15: II | C15: BASE DE CONOCIMIENTOS INTEGRADA | D15: Principio 02 | E15: Elaborar y mantener una base de conocimientos interdisciplinaria para respaldar la gestión de los relaves durante todo su ciclo de vida, incluido su cierre. | F15: Requisito 02.2 | G15: Requisito 02.2 Preparar, documentar y actualizar una caracterización del sitio detallada de la (las) instalación(es) de relaves que incluyan datos sobre el clima, geomorfología, geología, geoquímica, hidrología e hidrogeología (flujo y calidad de aguas superficiales y de subsuelo), geotécnicos y sísmicos. Las propiedades químicas y físicas del relave serán caracterizadas y actualizadas con regularidad para tomar en cuenta la variabilidad de las propiedades y procesamiento del mineral | H15: 2.2 - A | I15: 2.2 - A Existe una caracterización detallada1 del(los) sitio(s) de la instalación de relaves y se actualiza según se justifica a través del ciclo de vida, para reflejar los cambios materiales en las condiciones y nuevos conocimientos. | J15: =1/3 -> 0.33333333
A16: C015 | B16: II | C16: BASE DE CONOCIMIENTOS INTEGRADA | D16: Principio 02 | E16: Elaborar y mantener una base de conocimientos interdisciplinaria para respaldar la gestión de los relaves durante todo su ciclo de vida, incluido su cierre. | F16: Requisito 02.2 | G16: Requisito 02.2 Preparar, documentar y actualizar una caracterización del sitio detallada de la (las) instalación(es) de relaves que incluyan datos sobre el clima, geomorfología, geología, geoquímica, hidrología e hidrogeología (flujo y calidad de aguas superficiales y de subsuelo), geotécnicos y sísmicos. Las propiedades químicas y físicas del relave serán caracterizadas y actualizadas con regularidad para tomar en cuenta la variabilidad de las propiedades y procesamiento del mineral | H16: 2.2 - B | I16: 2.2 - B La caracterización del sitio es respaldada por datos incluyendo datos en clima, geomorfología, geología, geoquímica, hidrología, hidrogeología (flujo y calidad de aguas superficiales y subsuelo), geotécnicos y sísmicos). | J16: =1/3 -> 0.33333333
A17: C016 | B17: II | C17: BASE DE CONOCIMIENTOS INTEGRADA | D17: Principio 02 | E17: Elaborar y mantener una base de conocimientos interdisciplinaria para respaldar la gestión de los relaves durante todo su ciclo de vida, incluido su cierre. | F17: Requisito 02.2 | G17: Requisito 02.2 Preparar, documentar y actualizar una caracterización del sitio detallada de la (las) instalación(es) de relaves que incluyan datos sobre el clima, geomorfología, geología, geoquímica, hidrología e hidrogeología (flujo y calidad de aguas superficiales y de subsuelo), geotécnicos y sísmicos. Las propiedades químicas y físicas del relave serán caracterizadas y actualizadas con regularidad para tomar en cuenta la variabilidad de las propiedades y procesamiento del mineral | H17: 2.2 - C | I17: 2.2 - C Existe una caracterización de relaves, considerando las propiedades físicas y geoquímicas, y se actualizan a lo largo del ciclo de vida para tomar en cuenta la variabilidad en las propiedades y el procesamiento del mineral y la deposición de relaves. | J17: =1/3 -> 0.33333333
A18: C017 | B18: II | C18: BASE DE CONOCIMIENTOS INTEGRADA | D18: Principio 02 | E18: Elaborar y mantener una base de conocimientos interdisciplinaria para respaldar la gestión de los relaves durante todo su ciclo de vida, incluido su cierre. | F18: Requisito 02.3 | G18: Requisito 02.3 Desarrollar y documentar un análisis de brechas para la instalación de relaves, utilizando una metodología que considere modelos de falla creíble, condiciones del sitio, y las propiedades de las lamas. Los resultados del análisis estimarán el área física impactada por una falla potencial. Cuando materiales fluidos (agua o sólidos licuables) estén presentes en una instalación de relaves con una Clasificación de Consecuencias "Altas", "Muy Altas" o "Extremas", los resultados deben incluir estimados del área física impactada por la falla potencial, tiempos de llegada de flujo, profundidad y velocidades, y profundidad de la deposición de material. Actualizar cuando se dé un cambio material, ya sea a la instalación de relaves o al área física impactada. | H18: 2.3 - A | I18: 2.3 - A Donde una instalación de relaves tiene un modelo/escenario de falla creíble1, hay un análisis de brecha documentado para la instalación de relaves, utilizando una metodología que considere los modelos de falla creíbles, condiciones del sitio y propiedades de los relaves. | J18: =1/4 -> 0.25
A19: C018 | B19: II | C19: BASE DE CONOCIMIENTOS INTEGRADA | D19: Principio 02 | E19: Elaborar y mantener una base de conocimientos interdisciplinaria para respaldar la gestión de los relaves durante todo su ciclo de vida, incluido su cierre. | F19: Requisito 02.3 | G19: Requisito 02.3 Desarrollar y documentar un análisis de brechas para la instalación de relaves, utilizando una metodología que considere modelos de falla creíble, condiciones del sitio, y las propiedades de las lamas. Los resultados del análisis estimarán el área física impactada por una falla potencial. Cuando materiales fluidos (agua o sólidos licuables) estén presentes en una instalación de relaves con una Clasificación de Consecuencias "Altas", "Muy Altas" o "Extremas", los resultados deben incluir estimados del área física impactada por la falla potencial, tiempos de llegada de flujo, profundidad y velocidades, y profundidad de la deposición de material. Actualizar cuando se dé un cambio material, ya sea a la instalación de relaves o al área física impactada. | H19: 2.3 - B | I19: 2.3 - B El área física potencialmente afectada por una falla es estimada y definida. | J19: =1/4 -> 0.25
A20: C019 | B20: II | C20: BASE DE CONOCIMIENTOS INTEGRADA | D20: Principio 02 | E20: Elaborar y mantener una base de conocimientos interdisciplinaria para respaldar la gestión de los relaves durante todo su ciclo de vida, incluido su cierre. | F20: Requisito 02.3 | G20: Requisito 02.3 Desarrollar y documentar un análisis de brechas para la instalación de relaves, utilizando una metodología que considere modelos de falla creíble, condiciones del sitio, y las propiedades de las lamas. Los resultados del análisis estimarán el área física impactada por una falla potencial. Cuando materiales fluidos (agua o sólidos licuables) estén presentes en una instalación de relaves con una Clasificación de Consecuencias "Altas", "Muy Altas" o "Extremas", los resultados deben incluir estimados del área física impactada por la falla potencial, tiempos de llegada de flujo, profundidad y velocidades, y profundidad de la deposición de material. Actualizar cuando se dé un cambio material, ya sea a la instalación de relaves o al área física impactada. | H20: 2.3 - C | I20: 2.3 - C Para las instalaciones con escenarios de falla creíbles involucrando materiales fluidos (agua y sólidos licuables) y con una clasificación de consecuencias de “Altas”, “Muy Altas” o “Extremas”, se estiman los tiempos de llegada de flujo, profundidades de flujo, velocidades de flujo y profundidad del material depositado. | J20: =1/4 -> 0.25
A21: C020 | B21: II | C21: BASE DE CONOCIMIENTOS INTEGRADA | D21: Principio 02 | E21: Elaborar y mantener una base de conocimientos interdisciplinaria para respaldar la gestión de los relaves durante todo su ciclo de vida, incluido su cierre. | F21: Requisito 02.3 | G21: Requisito 02.3 Desarrollar y documentar un análisis de brechas para la instalación de relaves, utilizando una metodología que considere modelos de falla creíble, condiciones del sitio, y las propiedades de las lamas. Los resultados del análisis estimarán el área física impactada por una falla potencial. Cuando materiales fluidos (agua o sólidos licuables) estén presentes en una instalación de relaves con una Clasificación de Consecuencias "Altas", "Muy Altas" o "Extremas", los resultados deben incluir estimados del área física impactada por la falla potencial, tiempos de llegada de flujo, profundidad y velocidades, y profundidad de la deposición de material. Actualizar cuando se dé un cambio material, ya sea a la instalación de relaves o al área física impactada. | H21: 2.3 - D | I21: 2.3 - D Para las instalaciones que cumplen con las condiciones a, b y c, el análisis de brecha se completa/ actualiza si se da un cambio material 1 en la instalación de relaves o a la base de conocimientos que resulte en un escenario de falla creíble que pueda llevar a una falla de flujo. | J21: =1/4 -> 0.25
A22: C021 | B22: II | C22: BASE DE CONOCIMIENTOS INTEGRADA | D22: Principio 02 | E22: Elaborar y mantener una base de conocimientos interdisciplinaria para respaldar la gestión de los relaves durante todo su ciclo de vida, incluido su cierre. | F22: Requisito 02.4 | G22: Requisito 02.4 Para poder identificar los grupos de mayor riesgo, referirse al análisis de brechas actualizado de la instalación de relaves para evaluar y documentar la exposición y vulnerabilidad humana a los escenarios de falla creíble de la instalación de relaves. Actualizar la evaluación cuando se dé un cambio material, ya sea en la instalación de relaves o en la base del conocimiento | H22: 2.4 - A | I22: 2.4 - A Se identifican los grupos de mayor riesgo, considerando el análisis de brechas para aquellas instalaciones con escenarios de fallas creíbles según el Requisito 2.3. | J22: =1/3 -> 0.33333333
A23: C022 | B23: II | C23: BASE DE CONOCIMIENTOS INTEGRADA | D23: Principio 02 | E23: Elaborar y mantener una base de conocimientos interdisciplinaria para respaldar la gestión de los relaves durante todo su ciclo de vida, incluido su cierre. | F23: Requisito 02.4 | G23: Requisito 02.4 Para poder identificar los grupos de mayor riesgo, referirse al análisis de brechas actualizado de la instalación de relaves para evaluar y documentar la exposición y vulnerabilidad humana a los escenarios de falla creíble de la instalación de relaves. Actualizar la evaluación cuando se dé un cambio material, ya sea en la instalación de relaves o en la base del conocimiento | H23: 2.4 - B | I23: 2.4 - B Se documenta la exposición y vulnerabilidad humana potencial de los escenarios de fallas creíbles de la instalación de relaves. | J23: =1/3 -> 0.33333333
A24: C023 | B24: II | C24: BASE DE CONOCIMIENTOS INTEGRADA | D24: Principio 02 | E24: Elaborar y mantener una base de conocimientos interdisciplinaria para respaldar la gestión de los relaves durante todo su ciclo de vida, incluido su cierre. | F24: Requisito 02.4 | G24: Requisito 02.4 Para poder identificar los grupos de mayor riesgo, referirse al análisis de brechas actualizado de la instalación de relaves para evaluar y documentar la exposición y vulnerabilidad humana a los escenarios de falla creíble de la instalación de relaves. Actualizar la evaluación cuando se dé un cambio material, ya sea en la instalación de relaves o en la base del conocimiento | H24: 2.4 - C | I24: 2.4 - C La evaluación de la exposición y vulnerabilidad humana se actualiza si es que se da un cambio material 1 a la credibilidad de la falla de flujo potencial y su correspondiente análisis de brecha o base del conocimiento. | J24: =1/3 -> 0.33333333
A25: C024 | B25: II | C25: BASE DE CONOCIMIENTOS INTEGRADA | D25: Principio 03 | E25: Utilizar los elementos de la base de conocimientos – sociales, ambientales, de la economía local y técnicos – con el fin de informar las decisiones durante el ciclo de vida de la instalación de relaves, incluido su cierre | F25: Requisito 03.1 | G25: Requisito 03.1 Para mejorar la resistencia al cambio climático, evaluar, actualizar con regularidad y utilizar conocimientos del cambio climático a través del ciclo de vida de la instalación de relaves de acuerdo a los principios de la Gestión Adaptativa. | H25: 3.1 - A | I25: 3.1 - A Para mejorar la resistencia, se actualiza con regularidad el conocimiento sobre el cambio climático y se usa para evaluar los riesgos y oportunidades para el ciclo de vida de la instalación de relaves, en cumplimiento con los principios de gestión adaptativa, con la meta de mejorar la resistencia al cambio climático. | J25: 1
A26: C025 | B26: II | C26: BASE DE CONOCIMIENTOS INTEGRADA | D26: Principio 03 | E26: Utilizar los elementos de la base de conocimientos – sociales, ambientales, de la economía local y técnicos – con el fin de informar las decisiones durante el ciclo de vida de la instalación de relaves, incluido su cierre | F26: Requisito 03.2 | G26: Requisito 03.2 Para nuevas instalaciones de relaves, el Operador deberá utilizar la base de conocimientos y realizará un análisis de alternativas de criterio múltiple de todos los sitios, tecnologías y estrategias factibles para la gestión de relaves. El objetivo de este análisis será de: (i) seleccionar una alternativa que minimice los riesgos a las personas y medioambiente durante el ciclo de vida de la instalación de relaves, y (ii) minimiza el volumen de aguas y relaves colocados en instalaciones de relaves externas. Este análisis será un análisis objetivo de restricciones que será revisado por la Junta de Revisión Independiente de Relaves (ITRB) o un revisor técnico superior independiente. Para las instalaciones de relaves existentes, el Operador deberá revisar y refinar periódicamente las tecnologías y diseños de relaves, y las estrategias de gestión para minimizar riesgos y mejorar resultados medioambientales. Se aplicaría una excepción a las instalaciones que se demuestren estar en un estado de cierre seguro. | H26: 3.2 - A | I26: 3.2 A Para las nuevas instalaciones de relaves, un Análisis de Alternativas1 se realiza para examinar sitios, tecnologías y estrategias factibles para el tratamiento de relaves durante el ciclo de vida, que busca minimizar: - riesgos a las personas y medio ambiente; - volumen de relaves y aguas almacenados en instalaciones superficiales. | J26: =1/3 -> 0.33333333
A27: C026 | B27: II | C27: BASE DE CONOCIMIENTOS INTEGRADA | D27: Principio 03 | E27: Utilizar los elementos de la base de conocimientos – sociales, ambientales, de la economía local y técnicos – con el fin de informar las decisiones durante el ciclo de vida de la instalación de relaves, incluido su cierre | F27: Requisito 03.2 | G27: Requisito 03.2 Para nuevas instalaciones de relaves, el Operador deberá utilizar la base de conocimientos y realizará un análisis de alternativas de criterio múltiple de todos los sitios, tecnologías y estrategias factibles para la gestión de relaves. El objetivo de este análisis será de: (i) seleccionar una alternativa que minimice los riesgos a las personas y medioambiente durante el ciclo de vida de la instalación de relaves, y (ii) minimiza el volumen de aguas y relaves colocados en instalaciones de relaves externas. Este análisis será un análisis objetivo de restricciones que será revisado por la Junta de Revisión Independiente de Relaves (ITRB) o un revisor técnico superior independiente. Para las instalaciones de relaves existentes, el Operador deberá revisar y refinar periódicamente las tecnologías y diseños de relaves, y las estrategias de gestión para minimizar riesgos y mejorar resultados medioambientales. Se aplicaría una excepción a las instalaciones que se demuestren estar en un estado de cierre seguro. | H27: 3.2 - B | I27: 3.2 B Para instalaciones existentes que no estén en un estado de cierre seguro, hay revisiones periódicas de las tecnologías, diseños y estrategias de tratamiento de relaves, y evaluaciones del potencial para implementar mejoras que surjan de las revisiones. | J27: =1/3 -> 0.33333333
A28: C027 | B28: II | C28: BASE DE CONOCIMIENTOS INTEGRADA | D28: Principio 03 | E28: Utilizar los elementos de la base de conocimientos – sociales, ambientales, de la economía local y técnicos – con el fin de informar las decisiones durante el ciclo de vida de la instalación de relaves, incluido su cierre | F28: Requisito 03.2 | G28: Requisito 03.2 Para nuevas instalaciones de relaves, el Operador deberá utilizar la base de conocimientos y realizará un análisis de alternativas de criterio múltiple de todos los sitios, tecnologías y estrategias factibles para la gestión de relaves. El objetivo de este análisis será de: (i) seleccionar una alternativa que minimice los riesgos a las personas y medioambiente durante el ciclo de vida de la instalación de relaves, y (ii) minimiza el volumen de aguas y relaves colocados en instalaciones de relaves externas. Este análisis será un análisis objetivo de restricciones que será revisado por la Junta de Revisión Independiente de Relaves (ITRB) o un revisor técnico superior independiente. Para las instalaciones de relaves existentes, el Operador deberá revisar y refinar periódicamente las tecnologías y diseños de relaves, y las estrategias de gestión para minimizar riesgos y mejorar resultados medioambientales. Se aplicaría una excepción a las instalaciones que se demuestren estar en un estado de cierre seguro. | H28: 3.2 - C | I28: 3.2 C Para las nuevas instalaciones, el análisis es revisado por el ITRB o un revisor técnico superior independiente. | J28: =1/3 -> 0.33333333
A29: C028 | B29: II | C29: BASE DE CONOCIMIENTOS INTEGRADA | D29: Principio 03 | E29: Utilizar los elementos de la base de conocimientos – sociales, ambientales, de la economía local y técnicos – con el fin de informar las decisiones durante el ciclo de vida de la instalación de relaves, incluido su cierre | F29: Requisito 03.3 | G29: Requisito 03.3 Para las nuevas instalaciones de relaves, utilizar la base de conocimientos, incluyendo la incertidumbre debida al cambio climático para evaluar los impactos sociales, medioambientales y económicos locales de la instalación de relaves y su falla potencial a lo largo de su ciclo de vida. Donde las evaluaciones de impacto predicen impactos materiales agudos o crónicos, el Operador deberá desarrollar, documentar e implementar planes de mitigación y gestión usando la jerarquía de mitigación. | H29: 3.3 - A | I29: 3.3 - A Se realizan las evaluaciones de impacto medioambiental, social y económico locales y se informan a la base de conocimiento existente. | J29: =1/4 -> 0.25
A30: C029 | B30: II | C30: BASE DE CONOCIMIENTOS INTEGRADA | D30: Principio 03 | E30: Utilizar los elementos de la base de conocimientos – sociales, ambientales, de la economía local y técnicos – con el fin de informar las decisiones durante el ciclo de vida de la instalación de relaves, incluido su cierre | F30: Requisito 03.3 | G30: Requisito 03.3 Para las nuevas instalaciones de relaves, utilizar la base de conocimientos, incluyendo la incertidumbre debida al cambio climático para evaluar los impactos sociales, medioambientales y económicos locales de la instalación de relaves y su falla potencial a lo largo de su ciclo de vida. Donde las evaluaciones de impacto predicen impactos materiales agudos o crónicos, el Operador deberá desarrollar, documentar e implementar planes de mitigación y gestión usando la jerarquía de mitigación. | H30: 3.3 - B | I30: 3.3 - B Las evaluaciones ambientales, sociales y económico locales demuestran que las incertidumbres son consideradas en la evaluación de la vida de los impactos de las instalaciones de relaves y si hay algún potencial para una falla creíble a lo largo del ciclo de vida de la instalación de relaves. | J30: =1/4 -> 0.25
A31: C030 | B31: II | C31: BASE DE CONOCIMIENTOS INTEGRADA | D31: Principio 03 | E31: Utilizar los elementos de la base de conocimientos – sociales, ambientales, de la economía local y técnicos – con el fin de informar las decisiones durante el ciclo de vida de la instalación de relaves, incluido su cierre | F31: Requisito 03.3 | G31: Requisito 03.3 Para las nuevas instalaciones de relaves, utilizar la base de conocimientos, incluyendo la incertidumbre debida al cambio climático para evaluar los impactos sociales, medioambientales y económicos locales de la instalación de relaves y su falla potencial a lo largo de su ciclo de vida. Donde las evaluaciones de impacto predicen impactos materiales agudos o crónicos, el Operador deberá desarrollar, documentar e implementar planes de mitigación y gestión usando la jerarquía de mitigación. | H31: 3.3 - C | I31: 3.3 - C Medidas y planes de mitigación y gestión son desarrollados, documentados e implementados para abarcar los impactos materiales crónicos y agudos. | J31: =1/4 -> 0.25
A32: C031 | B32: II | C32: BASE DE CONOCIMIENTOS INTEGRADA | D32: Principio 03 | E32: Utilizar los elementos de la base de conocimientos – sociales, ambientales, de la economía local y técnicos – con el fin de informar las decisiones durante el ciclo de vida de la instalación de relaves, incluido su cierre | F32: Requisito 03.3 | G32: Requisito 03.3 Para las nuevas instalaciones de relaves, utilizar la base de conocimientos, incluyendo la incertidumbre debida al cambio climático para evaluar los impactos sociales, medioambientales y económicos locales de la instalación de relaves y su falla potencial a lo largo de su ciclo de vida. Donde las evaluaciones de impacto predicen impactos materiales agudos o crónicos, el Operador deberá desarrollar, documentar e implementar planes de mitigación y gestión usando la jerarquía de mitigación. | H32: 3.3 - D | I32: 3.3 - D Los planes de gestión se basan en los principios y prácticas de una jerarquía de mitigación y planes de gestión para la instalación de relaves y se actualizan a lo largo del ciclo de vida de la instalación de relaves. | J32: =1/4 -> 0.25
A33: C032 | B33: II | C33: BASE DE CONOCIMIENTOS INTEGRADA | D33: Principio 03 | E33: Utilizar los elementos de la base de conocimientos – sociales, ambientales, de la economía local y técnicos – con el fin de informar las decisiones durante el ciclo de vida de la instalación de relaves, incluido su cierre | F33: Requisito 03.4 | G33: Requisito 03.4 Actualizar la evaluación de los impactos sociales, medioambientales y económicos locales para reflejar un cambio material ya sea para la instalación de relaves o para el contexto social, medioambiental y económico local. Si nuevos datos indican que los impactos de la instalación de relaves han cambiado materialmente, incluso como el resultado de conocimiento del cambio climático o impactos a largo plazo, el Operador deberá actualizar la gestión de la instalación de relaves para reflejar los nuevos datos utilizando las mejores prácticas de Gestión Adaptativa. | H33: 3.4 - A | I33: 3.4 - A El cambio material como ha sido definido por el Operador es aplicado consistentemente para generar actualizaciones en las evaluaciones medioambientales, sociales y económicas de la instalación de relaves. | J33: =1/2 -> 0.5
A34: C033 | B34: II | C34: BASE DE CONOCIMIENTOS INTEGRADA | D34: Principio 03 | E34: Utilizar los elementos de la base de conocimientos – sociales, ambientales, de la economía local y técnicos – con el fin de informar las decisiones durante el ciclo de vida de la instalación de relaves, incluido su cierre | F34: Requisito 03.4 | G34: Requisito 03.4 Actualizar la evaluación de los impactos sociales, medioambientales y económicos locales para reflejar un cambio material ya sea para la instalación de relaves o para el contexto social, medioambiental y económico local. Si nuevos datos indican que los impactos de la instalación de relaves han cambiado materialmente, incluso como el resultado de conocimiento del cambio climático o impactos a largo plazo, el Operador deberá actualizar la gestión de la instalación de relaves para reflejar los nuevos datos utilizando las mejores prácticas de Gestión Adaptativa. | H34: 3.4 - B | I34: 3.4 - B Se actualiza la gestión de la instalación de relaves de acuerdo a las mejores prácticas de gestión adaptativa si nuevos datos (incluyendo conocimientos sobre cambio climático) indican que los impactos de la instalación de relaves han cambiado materialmente. | J34: =1/2 -> 0.5
A35: C034 | B35: III | C35: DISEÑO, CONSTRUCCIÓN, OPERACIÓN Y MONITOREO DE LAS INSTALACIONES DE RELAVES | D35: Principio 04 | E35: Desarrollar planes y criterios de diseño para la instalación de relaves con el fin de minimizar los riesgos para todas las fases del ciclo de vida, incluso el cierre y el post cierre. | F35: Requisito 04.1 | G35: Requisito 04.1 Determinar la consecuencia de la clasificación de fallas de la instalación de relaves al evaluar las condiciones de aguas abajo documentadas en la base de conocimientos y seleccionar la clasificación correspondiente a la Clasificación de Consecuencias más elevada para cada categoría en el Anexo 2, Tabla 1. La evaluación y selección de la clasificación se hará en base a los modelos de falla creíbles, y debe ser defendible y documentado. | H35: 4.1 - A | I35: 4.1 - A Se determina la clasificación de consecuencias de fallas de instalaciones de relaves al evaluar las condiciones aguas abajo documentadas en la base de conocimientos y adopta: (i) la clasificación de consecuencias para el nivel más alto en cada categoría en el Anexo 2, Tabla 1, o (ii) un enfoque más conservador mediante la adopción de criterios de diseño de carga post-cierre “Extremos” en el Anexo 2. | J35: =1/3 -> 0.33333333
A36: C035 | B36: III | C36: DISEÑO, CONSTRUCCIÓN, OPERACIÓN Y MONITOREO DE LAS INSTALACIONES DE RELAVES | D36: Principio 04 | E36: Desarrollar planes y criterios de diseño para la instalación de relaves con el fin de minimizar los riesgos para todas las fases del ciclo de vida, incluso el cierre y el post cierre. | F36: Requisito 04.1 | G36: Requisito 04.1 Determinar la consecuencia de la clasificación de fallas de la instalación de relaves al evaluar las condiciones de aguas abajo documentadas en la base de conocimientos y seleccionar la clasificación correspondiente a la Clasificación de Consecuencias más elevada para cada categoría en el Anexo 2, Tabla 1. La evaluación y selección de la clasificación se hará en base a los modelos de falla creíbles, y debe ser defendible y documentado. | H36: 4.1 - B | I36: 4.1 - B Para a(i) basar la evaluación y selección de la clasificación en modelos/escenarios de fallas creíbles. | J36: =1/3 -> 0.33333333
A37: C036 | B37: III | C37: DISEÑO, CONSTRUCCIÓN, OPERACIÓN Y MONITOREO DE LAS INSTALACIONES DE RELAVES | D37: Principio 04 | E37: Desarrollar planes y criterios de diseño para la instalación de relaves con el fin de minimizar los riesgos para todas las fases del ciclo de vida, incluso el cierre y el post cierre. | F37: Requisito 04.1 | G37: Requisito 04.1 Determinar la consecuencia de la clasificación de fallas de la instalación de relaves al evaluar las condiciones de aguas abajo documentadas en la base de conocimientos y seleccionar la clasificación correspondiente a la Clasificación de Consecuencias más elevada para cada categoría en el Anexo 2, Tabla 1. La evaluación y selección de la clasificación se hará en base a los modelos de falla creíbles, y debe ser defendible y documentado. | H37: 4.1 - C | I37: 4.1 - C Documentar la evaluación y selección con evidencia defendible. | J37: =1/3 -> 0.33333333
A38: C037 | B38: III | C38: DISEÑO, CONSTRUCCIÓN, OPERACIÓN Y MONITOREO DE LAS INSTALACIONES DE RELAVES | D38: Principio 04 | E38: Desarrollar planes y criterios de diseño para la instalación de relaves con el fin de minimizar los riesgos para todas las fases del ciclo de vida, incluso el cierre y el post cierre. | F38: Requisito 04.2 | G38: Requisito 04.2 Con el objetivo de mantener flexibilidad en el desarrollo de una nueva instalación de relaves y optimizar costos mientras se da prioridad a la seguridad durante el ciclo de vida de la instalación de relaves. a) Desarrollar diseños preliminares para la instalación de relaves con el criterio de carga de diseño externo consistente tanto con la clasificación de consecuencias de la falla en base a condiciones actuales y la Clasificación de Consecuencias mayor (incluyendo “Extrema”) - b) Informado por la gama de requisitos definidos por los diseños preliminares, ya sea: - Implementar el diseño para los criterios de carga de la Clasificación de Consecuencias “Extremas”; o - Implementar el diseño para el criterio de Clasificación de Consecuencias actual o uno más elevado, y demostrar factibilidad, a nivel de prueba de concepto, para mejorar el diseño para que el criterio de clasificación “Extrema” se mantenga a lo largo del ciclo de vida de la instalación de relaves. c) Si se implementa la opción B.2, revisar la clasificación de las consecuencias de la falla al momento de la Revisión de Seguridad de Represas (RSR) y por lo menos cada cinco años, o más pronto si se da un cambio material en el contexto social, medioambiental y económico local, y completar la actualización de la instalación de relaves acorde a la nueva Clasificación de Consecuencias según lo determinado por la RSR dentro de tres años. Esta revisión procederá hasta que la instalación de relaves haya sido cerrada de forma segura de acuerdo a este Estándar. d) El proceso descrito anteriormente será revisado por la Junta de Revisión de Relaves Independiente (ITRB) o el revisor técnico senior independiente, como sea adecuado para la Clasificación de Consecuencias de la instalación de relaves. Sujeto al Requisito 4.7, los Requisitos 4.2c y 4.2 también serán aplicados a instalaciones de relaves existentes. | H38: 4.2 - A | I38: 4.2 - A Se preparan diseños preliminares para la instalación de relaves, con consideración de las etapas del ciclo de vida, utilizando criterios de carga de diseños externos consistentes con la clasificación de consecuencias de fallas basada en condiciones actuales y la Clasificación de Consecuencias mayor (incluyendo “Extrema”). | J38: =1/5 -> 0.2
A39: C038 | B39: III | C39: DISEÑO, CONSTRUCCIÓN, OPERACIÓN Y MONITOREO DE LAS INSTALACIONES DE RELAVES | D39: Principio 04 | E39: Desarrollar planes y criterios de diseño para la instalación de relaves con el fin de minimizar los riesgos para todas las fases del ciclo de vida, incluso el cierre y el post cierre. | F39: Requisito 04.2 | G39: Requisito 04.2 Con el objetivo de mantener flexibilidad en el desarrollo de una nueva instalación de relaves y optimizar costos mientras se da prioridad a la seguridad durante el ciclo de vida de la instalación de relaves. a) Desarrollar diseños preliminares para la instalación de relaves con el criterio de carga de diseño externo consistente tanto con la clasificación de consecuencias de la falla en base a condiciones actuales y la Clasificación de Consecuencias mayor (incluyendo “Extrema”) - b) Informado por la gama de requisitos definidos por los diseños preliminares, ya sea: - Implementar el diseño para los criterios de carga de la Clasificación de Consecuencias “Extremas”; o - Implementar el diseño para el criterio de Clasificación de Consecuencias actual o uno más elevado, y demostrar factibilidad, a nivel de prueba de concepto, para mejorar el diseño para que el criterio de clasificación “Extrema” se mantenga a lo largo del ciclo de vida de la instalación de relaves. c) Si se implementa la opción B.2, revisar la clasificación de las consecuencias de la falla al momento de la Revisión de Seguridad de Represas (RSR) y por lo menos cada cinco años, o más pronto si se da un cambio material en el contexto social, medioambiental y económico local, y completar la actualización de la instalación de relaves acorde a la nueva Clasificación de Consecuencias según lo determinado por la RSR dentro de tres años. Esta revisión procederá hasta que la instalación de relaves haya sido cerrada de forma segura de acuerdo a este Estándar. d) El proceso descrito anteriormente será revisado por la Junta de Revisión de Relaves Independiente (ITRB) o el revisor técnico senior independiente, como sea adecuado para la Clasificación de Consecuencias de la instalación de relaves. Sujeto al Requisito 4.7, los Requisitos 4.2c y 4.2 también serán aplicados a instalaciones de relaves existentes. | H39: 4.2 - B | I39: 4.2 - B Adoptar (i) los criterios de carga externa de la Clasificación de Consecuencias “Extrema”, o (ii) adoptar los criterios de carga de la Clasificación de Consecuencias actual o una mayor, y demostrar la factibilidad, a nivel de prueba de concepto, para mejorar el diseño para que el criterio de clasificación “Extremo” se mantenga a lo largo del ciclo de vida de la instalación de relaves. | J39: =1/5 -> 0.2
A40: C039 | B40: III | C40: DISEÑO, CONSTRUCCIÓN, OPERACIÓN Y MONITOREO DE LAS INSTALACIONES DE RELAVES | D40: Principio 04 | E40: Desarrollar planes y criterios de diseño para la instalación de relaves con el fin de minimizar los riesgos para todas las fases del ciclo de vida, incluso el cierre y el post cierre. | F40: Requisito 04.2 | G40: Requisito 04.2 Con el objetivo de mantener flexibilidad en el desarrollo de una nueva instalación de relaves y optimizar costos mientras se da prioridad a la seguridad durante el ciclo de vida de la instalación de relaves. a) Desarrollar diseños preliminares para la instalación de relaves con el criterio de carga de diseño externo consistente tanto con la clasificación de consecuencias de la falla en base a condiciones actuales y la Clasificación de Consecuencias mayor (incluyendo “Extrema”) - b) Informado por la gama de requisitos definidos por los diseños preliminares, ya sea: - Implementar el diseño para los criterios de carga de la Clasificación de Consecuencias “Extremas”; o - Implementar el diseño para el criterio de Clasificación de Consecuencias actual o uno más elevado, y demostrar factibilidad, a nivel de prueba de concepto, para mejorar el diseño para que el criterio de clasificación “Extrema” se mantenga a lo largo del ciclo de vida de la instalación de relaves. c) Si se implementa la opción B.2, revisar la clasificación de las consecuencias de la falla al momento de la Revisión de Seguridad de Represas (RSR) y por lo menos cada cinco años, o más pronto si se da un cambio material en el contexto social, medioambiental y económico local, y completar la actualización de la instalación de relaves acorde a la nueva Clasificación de Consecuencias según lo determinado por la RSR dentro de tres años. Esta revisión procederá hasta que la instalación de relaves haya sido cerrada de forma segura de acuerdo a este Estándar. d) El proceso descrito anteriormente será revisado por la Junta de Revisión de Relaves Independiente (ITRB) o el revisor técnico senior independiente, como sea adecuado para la Clasificación de Consecuencias de la instalación de relaves. Sujeto al Requisito 4.7, los Requisitos 4.2c y 4.2 también serán aplicados a instalaciones de relaves existentes. | H40: 4.2 - C | I40: 4.2 - C Si la opción b(ii) anterior es implementada, la Clasificación de Consecuencias es revisada al momento de la Revisión de Seguridad de Represas (DRS) 1 y por lo menos cada cinco años, o antes si se da algún cambio material en el contexto social, medioambiental o económico local, y completar la mejora de la instalación de relaves conforme a la nueva Clasificación de Consecuencias determinada por la DSR dentro de tres años. Esta revisión procederá hasta que la instalación de relaves haya sido cerrada de forma segura de acuerdo a este Estándar. | J40: =1/5 -> 0.2
...

Sheet Criterios
A1: Codigo_Criterio | B1: ID_Criterio_Plataforma | C1: Tema | D1: Nombre del tema | E1: Principio | F1: Requisito | G1: Texto literal del criterio (ICMM, ES) | H1: Preguntas_clave | I1: Aplicabilidad | J1: Estado_mapeo | K1: N° documentos | L1: N° principales
A2: 1.1.a | B2: C001 | C2: I | D2: Comunidades afectadas | E2: 1 | F2: 1.1 | G2: El Operador tiene una política de compromiso para respetar los derechos humanos de acuerdo al UNGP. | H2: ¿Abarca compromiso(s) para respetar los derechos humanos de acuerdo al UNGP? | I2: Instalación existente | J2: Listo | K2: =COUNTIFS(Relacion_Doc_Criterio!$A:$A,A2,Relacion_Doc_Criterio!$D:$D,"<>") -> 1 | L2: =COUNTIFS(Relacion_Doc_Criterio!$A:$A,A2,Relacion_Doc_Criterio!$D:$D,"<>",Relacion_Doc_Criterio!#REF!,"Principal") -> #REF!
A3: 1.1.b | B3: C002 | C3: I | D3: Comunidades afectadas | E3: 1 | F3: 1.1 | G3: El Operador ha realizado el proceso de diligencias de derechos humanos específicas al sitio para informarlas decisiones de gestión a través del ciclo de vida de los relaves. | H3: ¿Contiene la evaluación y riesgos de los derechos humanos? ¿La debida diligencia es específica del sitio e incluye la instalación de relaves? ¿Hay evidencia de que los hallazgos se actualizan con regularidad y han informado decisiones de gestión a lo largo del tiempo (actas, medidas implementadas)? | I3: Instalación existente | J3: Listo | K3: =COUNTIFS(Relacion_Doc_Criterio!$A:$A,A3,Relacion_Doc_Criterio!$D:$D,"<>") -> 1 | L3: =COUNTIFS(Relacion_Doc_Criterio!$A:$A,A3,Relacion_Doc_Criterio!$D:$D,"<>",Relacion_Doc_Criterio!#REF!,"Principal") -> #REF!
A4: 1.1.c | B4: C003 | C4: I | D4: Comunidades afectadas | E4: 1 | F4: 1.1 | G4: El Operador ha abordado los riesgos a los derechos humanos de los escenarios de falla creíbles de la instalación de relaves donde aquellos escenarios existan para tal instalación. | H4: ¿Se ha identificado los escenarios de falla creíbles de la instalación de relaves? ¿Se ha evaluado los riesgos potenciales para los derechos humanos asociados a dichos escenarios? | I4: Instalación existente | J4: Listo | K4: =COUNTIFS(Relacion_Doc_Criterio!$A:$A,A4,Relacion_Doc_Criterio!$D:$D,"<>") -> 1 | L4: =COUNTIFS(Relacion_Doc_Criterio!$A:$A,A4,Relacion_Doc_Criterio!$D:$D,"<>",Relacion_Doc_Criterio!#REF!,"Principal") -> #REF!
A5: 1.2.a | B5: C004 | C5: I | D5: Comunidades afectadas | E5: 1 | F5: 1.2 | G5: El Operador ha identificado los grupos indígenas o tribales que puedan verse afectados por una nueva instalación de relaves, y entiende como los derechos de estas personas pueden verse impactados, incluyendo sus tierras y derechos a los recursos y su derecho a la libre determinación. | H5: ¿Cuenta con el registro de los grupos afectados por el proyecto? ¿Se presenta acuerdos de debida diligencia demostrando cómo se han considerado a los grupos indígenas y tribales? ¿Se cuentan con perfiles de línea base de los grupos indígenas o tribales incluyendo características comunales, culturales y de uso de tierras/recursos? ¿Se cuenta con evaluaciones riesgo/impacto pertinentes a los derechos de los grupos indígenas y tribales? ¿Se cuenta con planes diseñados para apoyar el compromiso significativo de los grupos indígenas y tribales, mediante un proceso mutuamente aceptable para el compromiso significativo y negociación de buena fe? | I5: Instalación existente | J5: Listo | K5: =COUNTIFS(Relacion_Doc_Criterio!$A:$A,A5,Relacion_Doc_Criterio!$D:$D,"<>") -> 1 | L5: =COUNTIFS(Relacion_Doc_Criterio!$A:$A,A5,Relacion_Doc_Criterio!$D:$D,"<>",Relacion_Doc_Criterio!#REF!,"Principal") -> #REF!
A6: 1.2.b | B6: C005 | C6: I | D6: Comunidades afectadas | E6: 1 | F6: 1.2 | G6: El Operador trabaja para obtener y mantener el CLPI por parte de los grupos indígenas o tribales, en cumplimiento con la guía internacional y marco de las mejores prácticas reconocidas. | H6: ¿Se detalla sobre la información compartida con los grupos afectados? ¿El acuerdo es aceptado mutuamente? ¿Hay registros de participación que muestren el compromiso respecto a los puntos de decisión clave del ciclo de vida de la instalación? | I6: Instalación existente | J6: Listo | K6: =COUNTIFS(Relacion_Doc_Criterio!$A:$A,A6,Relacion_Doc_Criterio!$D:$D,"<>") -> 1 | L6: =COUNTIFS(Relacion_Doc_Criterio!$A:$A,A6,Relacion_Doc_Criterio!$D:$D,"<>",Relacion_Doc_Criterio!#REF!,"Principal") -> #REF!
A7: 1.3.a | B7: C006 | C7: I | D7: Comunidades afectadas | E7: 1 | F7: 1.3 | G7: El Operador ha identificado a los grupos afectados por el proyecto. | H7: ¿Se identifica los grupos afectados por el proyecto? ¿El registro o mapa de actores indica ubicación y medio de participación de cada grupo? | I7: Instalación existente | J7: Listo | K7: =COUNTIFS(Relacion_Doc_Criterio!$A:$A,A7,Relacion_Doc_Criterio!$D:$D,"<>") -> 1 | L7: =COUNTIFS(Relacion_Doc_Criterio!$A:$A,A7,Relacion_Doc_Criterio!$D:$D,"<>",Relacion_Doc_Criterio!#REF!,"Principal") -> #REF!
A8: 1.3.b | B8: C007 | C8: I | D8: Comunidades afectadas | E8: 1 | F8: 1.3 | G8: El Operador ha asumido un compromiso significativo con los grupos afectados por el proyecto a través del ciclo de vida de la instalación de relaves para: – Compartir información relevante y accesible sobre la instalación de relaves; – Construir la base de conocimientos para la instalación de relaves, incluyendo el contexto social, medioambiental y económico local; y, – Buscar retroalimentación en las decisiones que pueden tener relación con la seguridad pública y la integridad de la instalación de relaves. | H8: ¿Se evidencia que la información de evaluaciones de riesgo, planes de emergencia y plan de cierre de la instalación de relaves es compartida con los grupos afectados? ¿Hay evidencia del registro de participación de los grupos afectados? | I8: Instalación existente | J8: Listo | K8: =COUNTIFS(Relacion_Doc_Criterio!$A:$A,A8,Relacion_Doc_Criterio!$D:$D,"<>") -> 1 | L8: =COUNTIFS(Relacion_Doc_Criterio!$A:$A,A8,Relacion_Doc_Criterio!$D:$D,"<>",Relacion_Doc_Criterio!#REF!,"Principal") -> #REF!
A9: 1.4.a | B9: C008 | C9: I | D9: Comunidades afectadas | E9: 1 | F9: 1.4 | G9: Se desarrolló e implementó un mecanismo de reclamos accesible y eficaz a nivel operativo para personas afectadas por el proyecto. | H9: ¿Se describe el proceso o mecanismo de las quejas y/o reclamos? ¿El mecanismo es accesible para las personas afectadas por la instalación de relaves? | I9: Instalación existente | J9: Listo | K9: =COUNTIFS(Relacion_Doc_Criterio!$A:$A,A9,Relacion_Doc_Criterio!$D:$D,"<>") -> 1 | L9: =COUNTIFS(Relacion_Doc_Criterio!$A:$A,A9,Relacion_Doc_Criterio!$D:$D,"<>",Relacion_Doc_Criterio!#REF!,"Principal") -> #REF!
A10: 1.4.b | B10: C009 | C10: I | D10: Comunidades afectadas | E10: 1 | F10: 1.4 | G10: El mecanismo de reclamos abarca quejas y agravios de las personas afectadas por el proyecto relacionado a la instalación de relaves. | H10: ¿Las quejas y/o reclamos se registran de forma sistemática? ¿Hay evidencia que las quejas y/o agravios están siendo abordados? | I10: Instalación existente | J10: Listo | K10: =COUNTIFS(Relacion_Doc_Criterio!$A:$A,A10,Relacion_Doc_Criterio!$D:$D,"<>") -> 1 | L10: =COUNTIFS(Relacion_Doc_Criterio!$A:$A,A10,Relacion_Doc_Criterio!$D:$D,"<>",Relacion_Doc_Criterio!#REF!,"Principal") -> #REF!
A11: 1.4.c | B11: C010 | C11: I | D11: Comunidades afectadas | E11: 1 | F11: 1.4 | G11: El mecanismo de reclamos brinda soluciones de acuerdo a las UNGPs 29-31. | H11: ¿Se indica cómo se dará respuesta a la queja y/o reclamo presentado? ¿Se demuestra la efectividad del mecanismo de reclamo según UNGP 29-31 (legitimidad, accesibilidad, previsibilidad, equidad, transparencia, aprendizaje continuo)? | I11: Instalación existente | J11: Listo | K11: =COUNTIFS(Relacion_Doc_Criterio!$A:$A,A11,Relacion_Doc_Criterio!$D:$D,"<>") -> 1 | L11: =COUNTIFS(Relacion_Doc_Criterio!$A:$A,A11,Relacion_Doc_Criterio!$D:$D,"<>",Relacion_Doc_Criterio!#REF!,"Principal") -> #REF!
A12: 2.1.a | B12: C011 | C12: II | D12: Base de conocimientos integrada | E12: 2 | F12: 2.1 | G12: El Operador ha documentado el contexto social, medioambiental y económico específico del sitio con respecto a su instalación de relaves. | H12: ¿Documenta la evaluación de impacto medioambiental y sociales? | I12: Instalación existente | J12: Listo | K12: =COUNTIFS(Relacion_Doc_Criterio!$A:$A,A12,Relacion_Doc_Criterio!$D:$D,"<>") -> 1 | L12: =COUNTIFS(Relacion_Doc_Criterio!$A:$A,A12,Relacion_Doc_Criterio!$D:$D,"<>",Relacion_Doc_Criterio!#REF!,"Principal") -> #REF!
A13: 2.1.b | B13: C012 | C13: II | D13: Base de conocimientos integrada | E13: 2 | F13: 2.1 | G13: Evalúa las incertidumbres asociadas al cambio climático que pueda impactar la seguridad de la instalación de relaves (véase también requisito GISTM 3.1) | H13: ¿Describe las evaluaciones asociadas al cambio climático? ¿Evalúa el efecto de condiciones hidrológicas variables sobre los escenarios de falla creíbles? | I13: Instalación existente | J13: Listo | K13: =COUNTIFS(Relacion_Doc_Criterio!$A:$A,A13,Relacion_Doc_Criterio!$D:$D,"<>") -> 1 | L13: =COUNTIFS(Relacion_Doc_Criterio!$A:$A,A13,Relacion_Doc_Criterio!$D:$D,"<>",Relacion_Doc_Criterio!#REF!,"Principal") -> #REF!
... A220: 15.3.b | B220: C219 | C220: VI | D220: Divulgación pública y acceso a la información | E220: 15 | F220: 15.3 | G220: Actualizar periódicamente la información divulgada relacionada a la seguridad e integridad de instalaciones de relaves, como mínimo de acuerdo a los requisitos en 15.1 | H220: ¿La información divulgada se actualiza periódicamente, al menos anualmente según el requisito 15.1? ¿Hay evidencia de fechas de actualización sucesivas (versiones o capturas fechadas)? | I220: Instalación existente | J220: Pendiente | K220: =COUNTIFS(Relacion_Doc_Criterio!$A:$A,A220,Relacion_Doc_Criterio!$D:$D,"<>") -> 1 | L220: =COUNTIFS(Relacion_Doc_Criterio!$A:$A,A220,Relacion_Doc_Criterio!$D:$D,"<>",Relacion_Doc_Criterio!#REF!,"Principal") -> #REF!

Sheet Catalogo_Documentos
A1: ID_Documento | B1: Documento | C1: Tipo Documento | D1: Código | E1: Estado | F1: % Avance Individual | G1: Consultor | H1: Área Responsable | I1: Fecha Iniciado | J1: Fecha RevA | K1: Fecha RevB | L1: Fecha Rev0 | M1: Frecuencia (meses) | N1: Caducidad | O1: URL | P1: Compañía | Q1: Depósito
A2: D001 | B2: Política corporativa de derechos humanos | C2: Política | D2: GA-DOC-01-2024 | E2: =IF(AND(L2>0,L2<>"-"),"Rev0",IF(AND(K2>0,K2<>"-"),"RevB",IF(AND(J2>0,J2<>"-"),"RevA",IF(AND(I2>0,I2<>"-"),"Iniciado","No Asignado")))) -> Rev0 | F2: {=_xlfn.IFS(E2="No Asignado",0,E2="Iniciado",0.2,E2="RevA",0.4,E2="RevB",0.7,E2="Rev0",1)} -> 1 | G2: Consultor 1 | H2: Sustentabilidad | I2: 45292 | J2: 45312 | K2: 45337 | L2: 45717 | M2: 36 | N2: 46797 | O2: https://drive.google.com/drive/folders/1IaEo6qPMz_Vb8OOQY3e1RIre4Fj4qXZL?usp=drive_link | P2: Mining Company | Q2: Embalse N°1
A3: D002 | B3: Debida deligencia de los derechos humanos | C3: Informe | D3: GA-DOC-01-2024 | E3: =IF(AND(L3>0,L3<>"-"),"Rev0",IF(AND(K3>0,K3<>"-"),"RevB",IF(AND(J3>0,J3<>"-"),"RevA",IF(AND(I3>0,I3<>"-"),"Iniciado","No Asignado")))) -> RevB | F3: {=_xlfn.IFS(E3="No Asignado",0,E3="Iniciado",0.2,E3="RevA",0.4,E3="RevB",0.7,E3="Rev0",1)} -> 0.7 | G3: Consultor 1 | H3: Sustentabilidad | I3: 45292 | J3: 45312 | K3: 45337 | L3: - | M3: 12 | N3: - | O3: https://drive.google.com/drive/folders/1IaEo6qPMz_Vb8OOQY3e1RIre4Fj4qXZL?usp=drive_link | P3: Mining Company | Q3: Embalse N°1
A4: D003 | B4: Caracterización detallada del sitio y relaves. | C4: Nota Técnica | D4: GA-DOC-01-2024 | E4: =IF(AND(L4>0,L4<>"-"),"Rev0",IF(AND(K4>0,K4<>"-"),"RevB",IF(AND(J4>0,J4<>"-"),"RevA",IF(AND(I4>0,I4<>"-"),"Iniciado","No Asignado")))) -> Iniciado | F4: {=_xlfn.IFS(E4="No Asignado",0,E4="Iniciado",0.2,E4="RevA",0.4,E4="RevB",0.7,E4="Rev0",1)} -> 0.2 | G4: Consultor 1 | H4: Sustentabilidad | I4: 45292 | J4: - | K4: - | L4: - | M4: 6 | N4: - | O4: https://drive.google.com/drive/folders/1IaEo6qPMz_Vb8OOQY3e1RIre4Fj4qXZL?usp=drive_link | P4: Mining Company | Q4: Embalse N°1
